Workbook

Sheet Valuation summary
B2: Summary various scenarios
B4: Scenario | C4: Share price
B5: Base scenario | C5: ='Valuation - base'!C91 -> 251.55499 | E5: BASE
B6: Lower growth, higher costs | C6: ='Valuation - lower margins'!C91 -> 154.33614 | E6: Price pressure, less services, more regulation, geopolitical
B7: Higher growth, higher profit | C7: ='Valuation - new product'!C91 -> 330.15228 | E7: New and more services - healthcare, iCloud for business, games, original content revenue

Sheet Valuation - base - in class
B2: IS and BS forecast, Free Cash Flows and Apple valuation
B3: BASE - estimated value as of November 2025
B5: Assumptions | C5: Actual | D5: Forecast | E5: Forecast | F5: Forecast | G5: Forecast | H5: Forecast | I5: Forecast | J5: Forecast
B6: Income statement | C6: 2025 | D6: 2026 | E6: 2027 | F6: 2028 | G6: 2029 | H6: 2030 | I6: 2031 | J6: 2032
B7: Sales growth | D7: ='Revenue forecast'!D27 -> 0.17067308 | E7: ='Revenue forecast'!E27 -> 0.11967146 | F7: ='Revenue forecast'!F27 -> 0.07918684 | G7: ='Revenue forecast'!G27 -> 0.07 | H7: ='Revenue forecast'!H27 -> 0.06 | I7: ='Revenue forecast'!I27 -> 0.05 | J7: ='Revenue forecast'!J27 -> 0.04 | L7: See the tab revenue forecast
B8: Cost of sales as % sales | C8: ='IS common size'!V6 -> 0.53094836 | D8: 0.51 | E8: 0.49 | F8: 0.47 | G8: =F8 -> 0.47 | H8: =G8 -> 0.47 | I8: =H8 -> 0.47 | J8: =I8 -> 0.47 | L8: Going down sligthly as a result of higher % of services as % of sales
B9: Ops expenses as % of sales | C9: ='IS common size'!V8 -> 0.14922109 | D9: =C9 -> 0.14922109 | E9: =D9 -> 0.14922109 | F9: =E9 -> 0.14922109 | G9: =F9 -> 0.14922109 | H9: =G9 -> 0.14922109 | I9: =H9 -> 0.14922109 | J9: =I9 -> 0.14922109 | L9: Stable
B10: Interest income | C10: 0.03 | D10: =C10 -> 0.03 | E10: 0.04 | F10: =E10 -> 0.04 | G10: =F10 -> 0.04 | H10: =G10 -> 0.04 | I10: =H10 -> 0.04 | J10: =I10 -> 0.04 | L10: Increasing at the interest rates increase
B11: Interest expense | C11: 0.05 | D11: =C11 -> 0.05 | E11: 0.05 | F11: =E11 -> 0.05 | G11: =F11 -> 0.05 | H11: =G11 -> 0.05 | I11: =H11 -> 0.05 | J11: =I11 -> 0.05 | L11: Increasing at the interest rates increase
B12: Tax rate as % of pretax income (going down) | C12: 0.2 | D12: =C12 -> 0.2 | E12: =D12 -> 0.2 | F12: =E12 -> 0.2 | G12: =F12 -> 0.2 | H12: =G12 -> 0.2 | I12: =H12 -> 0.2 | J12: =I12 -> 0.2 | L12: Based on the new tax rules
B13: Balance sheet
B14: Cash - stable in $ | C14: =C47 -> 35.934 | D14: =C14 -> 35.934 | E14: =D14 -> 35.934 | F14: =E14 -> 35.934 | G14: =F14 -> 35.934 | H14: =G14 -> 35.934 | I14: =H14 -> 35.934 | J14: =I14 -> 35.934 | L14: Stable
B15: ST debt - stable | C15: =C58 -> 20.329 | D15: =C15 -> 20.329 | E15: =D15 -> 20.329 | F15: =E15 -> 20.329 | G15: =F15 -> 20.329 | H15: =G15 -> 20.329 | I15: =H15 -> 20.329 | J15: =I15 -> 20.329 | L15: Stable
B16: LT debt - stable | C16: =C59 -> 78.328 | D16: =C16 -> 78.328 | E16: =D16 -> 78.328 | F16: =E16 -> 78.328 | G16: =F16 -> 78.328 | H16: =G16 -> 78.328 | I16: =H16 -> 78.328 | J16: =I16 -> 78.328 | L16: Stable
B17: AR as % of sales | C17: 0.058721746 | D17: =C17 -> 0.058721746 | E17: =D17 -> 0.058721746 | F17: =E17 -> 0.058721746 | G17: =F17 -> 0.058721746 | H17: =G17 -> 0.058721746 | I17: =H17 -> 0.058721746 | J17: =I17 -> 0.058721746 | L17: Stable
B18: Inventory as % of COGS | C18: 0.023950365 | D18: =C18 -> 0.023950365 | E18: =D18 -> 0.023950365 | F18: =E18 -> 0.023950365 | G18: =F18 -> 0.023950365 | H18: =G18 -> 0.023950365 | I18: =H18 -> 0.023950365 | J18: =I18 -> 0.023950365 | L18: Stable
B19: Goodwill + intangibles+other in $ | C19: =C53 -> 83.727 | D19: =C19 -> 83.727 | E19: =D19 -> 83.727 | F19: =E19 -> 83.727 | G19: =F19 -> 83.727 | H19: =G19 -> 83.727 | I19: =H19 -> 83.727 | J19: =I19 -> 83.727 | L19: Stable
B20: Other current assets as % of sales | C20: 0.11871482 | D20: =C20 -> 0.11871482 | E20: =D20 -> 0.11871482 | F20: =E20 -> 0.11871482 | G20: =F20 -> 0.11871482 | H20: =G20 -> 0.11871482 | I20: =H20 -> 0.11871482 | J20: =I20 -> 0.11871482 | L20: Stable
B21: AP as % of COGS | C21: 0.2494471 | D21: =C21 -> 0.2494471 | E21: =D21 -> 0.2494471 | F21: =E21 -> 0.2494471 | G21: =F21 -> 0.2494471 | H21: =G21 -> 0.2494471 | I21: =H21 -> 0.2494471 | J21: =I21 -> 0.2494471 | L21: Stable
B22: Accrued expenses as % of COGS | C22: 0.29091349 | D22: =C22 -> 0.29091349 | E22: =D22 -> 0.29091349 | F22: =E22 -> 0.29091349 | G22: =F22 -> 0.29091349 | H22: =G22 -> 0.29091349 | I22: =H22 -> 0.29091349 | J22: =I22 -> 0.29091349 | L22: Stable
B23: Non-current liabilities - no change | C23: =C60 -> 41.549 | D23: =C23 -> 41.549 | E23: =D23 -> 41.549 | F23: =E23 -> 41.549 | G23: =F23 -> 41.549 | H23: =G23 -> 41.549 | I23: =H23 -> 41.549 | J23: =I23 -> 41.549 | L23: Stable
B24: Other:
B25: Dividends in $ - increase of 5% per year | C25: 0.05 | D25: =C25 -> 0.05 | E25: =D25 -> 0.05 | F25: =E25 -> 0.05 | G25: =F25 -> 0.05 | H25: =G25 -> 0.05 | I25: =H25 -> 0.05 | J25: =I25 -> 0.05
B26: Share repurchases in $ - 80% of net income | C26: 0.8 | D26: 0.8 | E26: =D26 -> 0.8 | F26: =E26 -> 0.8 | G26: =F26 -> 0.8 | H26: =G26 -> 0.8 | I26: =H26 -> 0.8 | J26: =I26 -> 0.8
B27: Additional share repurchases/dividends to use foreign cash ($'B) | D27: 20 | E27: 20 | F27: 10 | G27: 10 | L27: Extra share repurchases
B28: CapEx as % of next year sales | C28: 0.03 | D28: 0.05 | E28: 0.07 | F28: =E28 -> 0.07 | G28: =F28 -> 0.07 | H28: =G28 -> 0.07 | I28: =H28 -> 0.07 | J28: =I28 -> 0.07 | L28: 3% is historical rate, just a bit gorwing because of potential data center needs
B29: Depreciation as % of current year CapEx | C29: 0.8 | D29: =C29 -> 0.8 | E29: =D29 -> 0.8 | F29: =E29 -> 0.8 | G29: =F29 -> 0.8 | H29: =G29 -> 0.8 | I29: =H29 -> 0.8 | J29: =I29 -> 0.8 | L29: Approximately the historical rate
B30: Growth rate - terminal | C30: 0.035
C32: Actual | D32: Forecast | E32: Forecast | F32: Forecast | G32: Forecast | H32: Forecast | I32: Forecast | J32: Forecast
B33: Income statement forecast | C33: =C6 -> 2025 | D33: =D6 -> 2026 | E33: =E6 -> 2027 | F33: =F6 -> 2028 | G33: =G6 -> 2029 | H33: =H6 -> 2030 | I33: =I6 -> 2031 | J33: =J6 -> 2032
B34: Net sales | C34: =IS!V4 -> 416.161 | L34: See the tab revenue forecast
B35: Cost of sales | C35: =IS!V5 -> -220.96
B36: Gross margin | C36: =SUM(C34:C35) -> 195.201
B37: Total operating expenses | C37: =IS!V7 -> -62.1
B38: Operating income | C38: =SUM(C36:C37) -> 133.101
B39: Interest income
B40: Interest expense
B41: Income before provision for income taxes | C41: =IS!V12 -> 132.729
B42: Provision for income taxes | C42: =IS!V13 -> -20.719
B43: Net income | C43: =SUM(C41:C42) -> 112.01
...

Sheet Valuation - base
B2: IS and BS forecast, Free Cash Flows and Apple valuation
B3: BASE - estimated value as of November 2025
B5: Assumptions | C5: Actual | D5: Forecast | E5: Forecast | F5: Forecast | G5: Forecast | H5: Forecast | I5: Forecast | J5: Forecast
B6: Income statement | C6: 2025 | D6: 2026 | E6: 2027 | F6: 2028 | G6: 2029 | H6: 2030 | I6: 2031 | J6: 2032
B7: Sales growth | D7: ='Revenue forecast'!D27 -> 0.17067308 | E7: ='Revenue forecast'!E27 -> 0.11967146 | F7: ='Revenue forecast'!F27 -> 0.07918684 | G7: ='Revenue forecast'!G27 -> 0.07 | H7: ='Revenue forecast'!H27 -> 0.06 | I7: ='Revenue forecast'!I27 -> 0.05 | J7: ='Revenue forecast'!J27 -> 0.04 | L7: See the tab revenue forecast
B8: Cost of sales as % sales | C8: ='IS common size'!V6 -> 0.53094836 | D8: 0.51 | E8: 0.49 | F8: 0.47 | G8: =F8 -> 0.47 | H8: =G8 -> 0.47 | I8: =H8 -> 0.47 | J8: =I8 -> 0.47 | L8: Going down sligthly as a result of higher % of services as % of sales
B9: Ops expenses as % of sales | C9: ='IS common size'!V8 -> 0.14922109 | D9: =C9 -> 0.14922109 | E9: =D9 -> 0.14922109 | F9: =E9 -> 0.14922109 | G9: =F9 -> 0.14922109 | H9: =G9 -> 0.14922109 | I9: =H9 -> 0.14922109 | J9: =I9 -> 0.14922109 | L9: Stable
B10: Interest income | C10: 0.03 | D10: =C10 -> 0.03 | E10: 0.04 | F10: =E10 -> 0.04 | G10: =F10 -> 0.04 | H10: =G10 -> 0.04 | I10: =H10 -> 0.04 | J10: =I10 -> 0.04 | L10: Increasing at the interest rates increase
B11: Interest expense | C11: 0.05 | D11: =C11 -> 0.05 | E11: 0.05 | F11: =E11 -> 0.05 | G11: =F11 -> 0.05 | H11: =G11 -> 0.05 | I11: =H11 -> 0.05 | J11: =I11 -> 0.05 | L11: Increasing at the interest rates increase
B12: Tax rate as % of pretax income (going down) | C12: 0.2 | D12: =C12 -> 0.2 | E12: =D12 -> 0.2 | F12: =E12 -> 0.2 | G12: =F12 -> 0.2 | H12: =G12 -> 0.2 | I12: =H12 -> 0.2 | J12: =I12 -> 0.2 | L12: Based on the new tax rules
B13: Balance sheet
B14: Cash - stable in $ | C14: =C47 -> 35.934 | D14: =C14 -> 35.934 | E14: =D14 -> 35.934 | F14: =E14 -> 35.934 | G14: =F14 -> 35.934 | H14: =G14 -> 35.934 | I14: =H14 -> 35.934 | J14: =I14 -> 35.934 | L14: Stable
B15: ST debt - stable | C15: =C58 -> 20.329 | D15: =C15 -> 20.329 | E15: =D15 -> 20.329 | F15: =E15 -> 20.329 | G15: =F15 -> 20.329 | H15: =G15 -> 20.329 | I15: =H15 -> 20.329 | J15: =I15 -> 20.329 | L15: Stable
B16: LT debt - stable | C16: =C59 -> 78.328 | D16: =C16 -> 78.328 | E16: =D16 -> 78.328 | F16: =E16 -> 78.328 | G16: =F16 -> 78.328 | H16: =G16 -> 78.328 | I16: =H16 -> 78.328 | J16: =I16 -> 78.328 | L16: Stable
B17: AR as % of sales | C17: 0.058721746 | D17: =C17 -> 0.058721746 | E17: =D17 -> 0.058721746 | F17: =E17 -> 0.058721746 | G17: =F17 -> 0.058721746 | H17: =G17 -> 0.058721746 | I17: =H17 -> 0.058721746 | J17: =I17 -> 0.058721746 | L17: Stable
B18: Inventory as % of COGS | C18: 0.023950365 | D18: =C18 -> 0.023950365 | E18: =D18 -> 0.023950365 | F18: =E18 -> 0.023950365 | G18: =F18 -> 0.023950365 | H18: =G18 -> 0.023950365 | I18: =H18 -> 0.023950365 | J18: =I18 -> 0.023950365 | L18: Stable
B19: Goodwill + intangibles+other in $ | C19: =C53 -> 83.727 | D19: =C19 -> 83.727 | E19: =D19 -> 83.727 | F19: =E19 -> 83.727 | G19: =F19 -> 83.727 | H19: =G19 -> 83.727 | I19: =H19 -> 83.727 | J19: =I19 -> 83.727 | L19: Stable
B20: Other current assets as % of sales | C20: 0.11871482 | D20: =C20 -> 0.11871482 | E20: =D20 -> 0.11871482 | F20: =E20 -> 0.11871482 | G20: =F20 -> 0.11871482 | H20: =G20 -> 0.11871482 | I20: =H20 -> 0.11871482 | J20: =I20 -> 0.11871482 | L20: Stable
B21: AP as % of COGS | C21: 0.2494471 | D21: =C21 -> 0.2494471 | E21: =D21 -> 0.2494471 | F21: =E21 -> 0.2494471 | G21: =F21 -> 0.2494471 | H21: =G21 -> 0.2494471 | I21: =H21 -> 0.2494471 | J21: =I21 -> 0.2494471 | L21: Stable
B22: Accrued expenses as % of COGS | C22: 0.29091349 | D22: =C22 -> 0.29091349 | E22: =D22 -> 0.29091349 | F22: =E22 -> 0.29091349 | G22: =F22 -> 0.29091349 | H22: =G22 -> 0.29091349 | I22: =H22 -> 0.29091349 | J22: =I22 -> 0.29091349 | L22: Stable
B23: Non-current liabilities - no change | C23: =C60 -> 41.549 | D23: =C23 -> 41.549 | E23: =D23 -> 41.549 | F23: =E23 -> 41.549 | G23: =F23 -> 41.549 | H23: =G23 -> 41.549 | I23: =H23 -> 41.549 | J23: =I23 -> 41.549 | L23: Stable
B24: Other:
B25: Dividends in $ - increase of 5% per year | C25: 0.05 | D25: =C25 -> 0.05 | E25: =D25 -> 0.05 | F25: =E25 -> 0.05 | G25: =F25 -> 0.05 | H25: =G25 -> 0.05 | I25: =H25 -> 0.05 | J25: =I25 -> 0.05
B26: Share repurchases in $ - 80% of net income | C26: 0.8 | D26: 0.8 | E26: =D26 -> 0.8 | F26: =E26 -> 0.8 | G26: =F26 -> 0.8 | H26: =G26 -> 0.8 | I26: =H26 -> 0.8 | J26: =I26 -> 0.8
B27: Additional share repurchases/dividends to use foreign cash ($'B) | D27: 20 | E27: 20 | F27: 10 | G27: 10 | L27: Extra share repurchases
B28: CapEx as % of next year sales | C28: 0.03 | D28: 0.05 | E28: 0.07 | F28: =E28 -> 0.07 | G28: =F28 -> 0.07 | H28: =G28 -> 0.07 | I28: =H28 -> 0.07 | J28: =I28 -> 0.07 | L28: 3% is historical rate, just a bit gorwing because of potential data center needs
B29: Depreciation as % of current year CapEx | C29: 0.8 | D29: =C29 -> 0.8 | E29: =D29 -> 0.8 | F29: =E29 -> 0.8 | G29: =F29 -> 0.8 | H29: =G29 -> 0.8 | I29: =H29 -> 0.8 | J29: =I29 -> 0.8 | L29: Approximately the historical rate
B30: Growth rate - terminal | C30: 0.035
C32: Actual | D32: Forecast | E32: Forecast | F32: Forecast | G32: Forecast | H32: Forecast | I32: Forecast | J32: Forecast
B33: Income statement forecast | C33: =C6 -> 2025 | D33: =D6 -> 2026 | E33: =E6 -> 2027 | F33: =F6 -> 2028 | G33: =G6 -> 2029 | H33: =H6 -> 2030 | I33: =I6 -> 2031 | J33: =J6 -> 2032
B34: Net sales | C34: =IS!V4 -> 416.161 | D34: ='Revenue forecast'!D22 -> 487 | E34: ='Revenue forecast'!E22 -> 545.28 | F34: ='Revenue forecast'!F22 -> 588.459 | G34: ='Revenue forecast'!G22 -> 629.65113 | H34: ='Revenue forecast'!H22 -> 667.4302 | I34: ='Revenue forecast'!I22 -> 700.80171 | J34: ='Revenue forecast'!J22 -> 728.83378 | L34: See the tab revenue forecast
B35: Cost of sales | C35: =IS!V5 -> -220.96 | D35: =-D34*D8 -> -248.37 | E35: =-E34*E8 -> -267.1872 | F35: =-F34*F8 -> -276.57573 | G35: =-G34*G8 -> -295.93603 | H35: =-H34*H8 -> -313.69219 | I35: =-I34*I8 -> -329.3768 | J35: =-J34*J8 -> -342.55187
B36: Gross margin | C36: =SUM(C34:C35) -> 195.201 | D36: =SUM(D34:D35) -> 238.63 | E36: =SUM(E34:E35) -> 278.0928 | F36: =SUM(F34:F35) -> 311.88327 | G36: =SUM(G34:G35) -> 333.7151 | H36: =SUM(H34:H35) -> 353.738 | I36: =SUM(I34:I35) -> 371.42491 | J36: =SUM(J34:J35) -> 386.2819
B37: Total operating expenses | C37: =IS!V7 -> -62.1 | D37: =-D34*D9 -> -72.670673 | E37: =-E34*E9 -> -81.367279 | F37: =-F34*F9 -> -87.810496 | G37: =-G34*G9 -> -93.957231 | H37: =-H34*H9 -> -99.594665 | I37: =-I34*I9 -> -104.5744 | J37: =-J34*J9 -> -108.75737
B38: Operating income | C38: =SUM(C36:C37) -> 133.101 | D38: =SUM(D36:D37) -> 165.95933 | E38: =SUM(E36:E37) -> 196.72552 | F38: =SUM(F36:F37) -> 224.07277 | G38: =SUM(G36:G37) -> 239.75787 | H38: =SUM(H36:H37) -> 254.14334 | I38: =SUM(I36:I37) -> 266.85051 | J38: =SUM(J36:J37) -> 277.52453
B39: Interest income | D39: =D10*C48 -> 2.89458 | E39: =E10*D48 -> 2.8527106 | F39: =F10*E48 -> 2.2824597 | G39: =G10*F48 -> 2.1398552 | H39: =H10*G48 -> 2.2609205 | I39: =I10*H48 -> 2.8107626 | J39: =J10*I48 -> 3.3956528
B40: Interest expense | D40: =-D11*(C58+C59) -> -4.93285 | E40: =-E11*(D58+D59) -> -4.93285 | F40: =-F11*(E58+E59) -> -4.93285 | G40: =-G11*(F58+F59) -> -4.93285 | H40: =-H11*(G58+G59) -> -4.93285 | I40: =-I11*(H58+H59) -> -4.93285 | J40: =-J11*(I58+I59) -> -4.93285
B41: Income before provision for income taxes | C41: =IS!V12 -> 132.729 | D41: =SUM(D38:D40) -> 163.92106 | E41: =SUM(E38:E40) -> 194.64538 | F41: =SUM(F38:F40) -> 221.42238 | G41: =SUM(G38:G40) -> 236.96487 | H41: =SUM(H38:H40) -> 251.47141 | I41: =SUM(I38:I40) -> 264.72842 | J41: =SUM(J38:J40) -> 275.98733
B42: Provision for income taxes | C42: =IS!V13 -> -20.719 | D42: =-D41*D12 -> -32.784211 | E42: =-E41*E12 -> -38.929076 | F42: =-F41*F12 -> -44.284477 | G42: =-G41*G12 -> -47.392975 | H42: =-H41*H12 -> -50.294282 | I42: =-I41*I12 -> -52.945684 | J42: =-J41*J12 -> -55.197466
B43: Net income | C43: =SUM(C41:C42) -> 112.01 | D43: =SUM(D41:D42) -> 131.13685 | E43: =SUM(E41:E42) -> 155.71631 | F43: =SUM(F41:F42) -> 177.13791 | G43: =SUM(G41:G42) -> 189.5719 | H43: =SUM(H41:H42) -> 201.17713 | I43: =SUM(I41:I42) -> 211.78274 | J43: =SUM(J41:J42) -> 220.78986
...

Sheet Forecast vs Actuals 2025
B2: Forecast versus actuals - 2025
B4: Income statement forecast | C4: Forecast - April 2025 | D4: Actuals - September 2025 | E4: Difference Actual - Forecast | G4: Comments
B5: Net sales | C5: 430.05 | D5: 416.161 | E5: =D5-C5 -> -13.889 | G5: A bit lower revenue than I projected :-(
B6: Cost of sales | C6: -223.626 | D6: -220.96 | E6: =D6-C6 -> 2.666 | G6: Very close
B7: Gross margin | C7: 206.424 | D7: 195.201 | E7: =D7-C7 -> -11.223 | G7: Because of the revenue miss
B8: Total operating expenses | C8: -55.9065 | D8: -62.1 | E8: =D8-C8 -> -6.1935 | G8: Lower revenue and higher ops expenses is why the ops income is off
B9: Operating income | C9: 150.5175 | D9: 133.101 | E9: =D9-C9 -> -17.4165
B10: Interest income
B11: Interest expense
B12: Income before provision for income taxes | C12: 148.9775 | D12: 132.729 | E12: =D12-C12 -> -16.2485
B13: Provision for income taxes | C13: -29.7955 | D13: -20.719 | E13: =D13-C13 -> 9.0765
B14: Net income | C14: 119.182 | D14: 112.01 | E14: =D14-C14 -> -7.172
B16: Balance sheet forecast | C16: =C4 -> Forecast - April 2025 | D16: =D4 -> Actuals - September 2025 | E16: Difference Actual - Forecast
B17: Cash and cash equivalents | C17: 30 | D17: 35.934 | E17: =D17-C17 -> 5.934 | G17: This is very close
B18: Marketable securities - ST and LT | C18: 103.3306 | D18: 96.486 | E18: =D18-C18 -> -6.8445983 | G18: And this one
B19: Accounts receivable, less allowances | C19: 25.253287 | D19: 39.777 | E19: =D19-C19 -> 14.523713 | G19: Probably just timing
B20: Inventories | C20: 5.3559244 | D20: 5.718 | E20: =D20-C20 -> 0.3620756
B21: Other current assets | C21: 51.05331 | D21: 47.765 | E21: =D21-C21 -> -3.2883102
B22: Property, plant and equipment, net | C22: 48.850156 | D22: 49.834 | E22: =D22-C22 -> 0.983844
B23: Goodwill + intangibles + other | C23: 75 | D23: 83.727 | E23: =D23-C23 -> 8.727
B24: Total assets | C24: 338.84328 | D24: 359.241 | E24: =D24-C24 -> 20.397724
B26: Accounts payable | C26: 55.782856 | D26: 69.86 | E26: =D26-C26 -> 14.077144 | G26: Basically slower collections and slower payments
B27: Accrued expenses | C27: 65.05582 | D27: 75.442 | E27: =D27-C27 -> 10.38618
B28: ST debt | C28: 21 | D28: 20.329 | E28: =D28-C28 -> -0.671
B29: Long-term debt | C29: 86 | D29: 78.328 | E29: =D29-C29 -> -7.672
B30: Non-current liabilities | C30: 54 | D30: 41.549 | E30: =D30-C30 -> -12.451
B31: Total liabilities | C31: 281.83868 | D31: 285.508 | E31: =D31-C31 -> 3.6693244
B32: Total shareholders' equity | C32: 57.0046 | D32: 73.733 | E32: =D32-C32 -> 16.7284 | G32: I expected higher share repurchases
B33: Total liabilities and equity | C33: 338.84328 | D33: 359.241 | E33: =D33-C33 -> 20.397724
B35: Other
B36: Dividends | C36: 15.54 | D36: 15 | E36: =D36-C36 -> -0.54
B37: Share repurchases | C37: 103 | D37: 91 | E37: =D37-C37 -> -12

Sheet Revenue forecast
B2: Apple revenue forecast as of November 2025
C4: Actual | D4: Forecast | E4: Forecast | F4: Forecast | G4: Forecast | H4: Forecast | I4: Forecast | J4: Forecast
B5: Volume by product | C5: 2025 | D5: 2026 | E5: 2027 | F5: 2028 | G5: 2029 | H5: 2030 | I5: 2031 | J5: 2032
B6: iPhone (in M) | D6: 260 | E6: 270 | F6: 270 | L6: From JPM projections
B7: iPad (in M) | D7: 70 | E7: 60 | F7: 60 | L7: From JPM projections
B9: Price by product | C9: =C5 -> 2025 | D9: =D5 -> 2026 | E9: =E5 -> 2027 | F9: =F5 -> 2028 | G9: =G5 -> 2029 | H9: =H5 -> 2030 | I9: =I5 -> 2031 | J9: =J5 -> 2032
B10: iPhone (in $) - blended | D10: 950 | E10: 1050 | F10: 1100 | L10: From JPM projections
B11: iPad (in $) - blended | D11: 480 | E11: 470 | F11: 450 | L11: From JPM projections
B13: Other products growth | C13: =C5 -> 2025 | D13: =D5 -> 2026 | E13: =E5 -> 2027 | F13: =F5 -> 2028 | G13: =G5 -> 2029 | H13: =H5 -> 2030 | I13: =I5 -> 2031 | J13: =J5 -> 2032
B14: Mac, iWatch, iPods | C14: 0.05 | D14: 0.08 | E14: 0.1 | F14: 0.1 | L14: From JPM projections
B15: Services | C15: 0.14 | D15: 0.2 | E15: 0.15 | F15: 0.15 | L15: From JPM projections
B17: Total revenue in $'B | C17: =C13 -> 2025 | D17: =D13 -> 2026 | E17: =E13 -> 2027 | F17: =F13 -> 2028 | G17: =G13 -> 2029 | H17: =H13 -> 2030 | I17: =I13 -> 2031 | J17: =J13 -> 2032
B18: iPhone | C18: 209 | D18: =D6*D10/1000 -> 247 | E18: =E6*E10/1000 -> 283.5 | F18: =F6*F10/1000 -> 297
B19: iPad | C19: 28 | D19: =D7*D11/1000 -> 33.6 | E19: =E7*E11/1000 -> 28.2 | F19: =F7*F11/1000 -> 27
B20: Other products | C20: 70 | D20: =C20*(1+D14) -> 75.6 | E20: =D20*(1+E14) -> 83.16 | F20: =E20*(1+F14) -> 91.476
B21: Services | C21: 109 | D21: =C21*(1+D15) -> 130.8 | E21: =D21*(1+E15) -> 150.42 | F21: =E21*(1+F15) -> 172.983
B22: Total | C22: =SUM(C18:C21) -> 416 | D22: =SUM(D18:D21) -> 487 | E22: =SUM(E18:E21) -> 545.28 | F22: =SUM(F18:F21) -> 588.459 | G22: =F22*(1+G27) -> 629.65113 | H22: =G22*(1+H27) -> 667.4302 | I22: =H22*(1+I27) -> 700.80171 | J22: =I22*(1+J27) -> 728.83378
C25: Calculated | D25: Calculated | E25: Calculated | F25: Calculated | G25: Estimate | H25: Estimate | I25: Estimate | J25: Estimate
C26: =C17 -> 2025 | D26: =D17 -> 2026 | E26: =E17 -> 2027 | F26: =F17 -> 2028 | G26: =G17 -> 2029 | H26: =H17 -> 2030 | I26: =I17 -> 2031 | J26: =J17 -> 2032
B27: Total revenue growth rate | D27: =D22/C22-1 -> 0.17067308 | E27: =E22/D22-1 -> 0.11967146 | F27: =F22/E22-1 -> 0.07918684 | G27: 0.07 | H27: 0.06 | I27: 0.05 | J27: 0.04

Sheet Valuation - new product
B2: IS and BS forecast, Free Cash Flows and Apple valuation
B3: BASE - estimated value as of November 2025
B5: Assumptions | C5: Actual | D5: Forecast | E5: Forecast | F5: Forecast | G5: Forecast | H5: Forecast | I5: Forecast | J5: Forecast
B6: Income statement | C6: 2025 | D6: 2026 | E6: 2027 | F6: 2028 | G6: 2029 | H6: 2030 | I6: 2031 | J6: 2032
B7: Sales growth | D7: ='Revenue forecast'!D27 -> 0.17067308 | E7: 0.15 | F7: 0.2 | G7: 0.15 | H7: 0.1 | I7: ='Revenue forecast'!I27 -> 0.05 | J7: ='Revenue forecast'!J27 -> 0.04 | L7: New product and higher revenue
B8: Cost of sales as % sales | C8: ='IS common size'!V6 -> 0.53094836 | D8: 0.5 | E8: 0.48 | F8: 0.46 | G8: 0.45 | H8: =G8 -> 0.45 | I8: =H8 -> 0.45 | J8: =I8 -> 0.45 | L8: Higher margins mainly because of the new product
B9: Ops expenses as % of sales | C9: ='IS common size'!V8 -> 0.14922109 | D9: =C9 -> 0.14922109 | E9: =D9 -> 0.14922109 | F9: =E9 -> 0.14922109 | G9: =F9 -> 0.14922109 | H9: =G9 -> 0.14922109 | I9: =H9 -> 0.14922109 | J9: =I9 -> 0.14922109 | L9: Stable
B10: Interest income | C10: 0.03 | D10: =C10 -> 0.03 | E10: 0.04 | F10: =E10 -> 0.04 | G10: =F10 -> 0.04 | H10: =G10 -> 0.04 | I10: =H10 -> 0.04 | J10: =I10 -> 0.04 | L10: Increasing at the interest rates increase
B11: Interest expense | C11: 0.05 | D11: =C11 -> 0.05 | E11: 0.05 | F11: =E11 -> 0.05 | G11: =F11 -> 0.05 | H11: =G11 -> 0.05 | I11: =H11 -> 0.05 | J11: =I11 -> 0.05 | L11: Increasing at the interest rates increase
B12: Tax rate as % of pretax income (going down) | C12: 0.2 | D12: =C12 -> 0.2 | E12: =D12 -> 0.2 | F12: =E12 -> 0.2 | G12: =F12 -> 0.2 | H12: =G12 -> 0.2 | I12: =H12 -> 0.2 | J12: =I12 -> 0.2 | L12: Based on the new tax rules
B13: Balance sheet
B14: Cash - stable in $ | C14: =C47 -> 35.934 | D14: =C14 -> 35.934 | E14: =D14 -> 35.934 | F14: =E14 -> 35.934 | G14: =F14 -> 35.934 | H14: =G14 -> 35.934 | I14: =H14 -> 35.934 | J14: =I14 -> 35.934 | L14: Stable
B15: ST debt - stable | C15: =C58 -> 20.329 | D15: =C15 -> 20.329 | E15: =D15 -> 20.329 | F15: =E15 -> 20.329 | G15: =F15 -> 20.329 | H15: =G15 -> 20.329 | I15: =H15 -> 20.329 | J15: =I15 -> 20.329 | L15: Stable
B16: LT debt - stable | C16: =C59 -> 78.328 | D16: =C16 -> 78.328 | E16: =D16 -> 78.328 | F16: =E16 -> 78.328 | G16: =F16 -> 78.328 | H16: =G16 -> 78.328 | I16: =H16 -> 78.328 | J16: =I16 -> 78.328 | L16: Stable
B17: AR as % of sales | C17: 0.058721746 | D17: =C17 -> 0.058721746 | E17: =D17 -> 0.058721746 | F17: =E17 -> 0.058721746 | G17: =F17 -> 0.058721746 | H17: =G17 -> 0.058721746 | I17: =H17 -> 0.058721746 | J17: =I17 -> 0.058721746 | L17: Stable
B18: Inventory as % of COGS | C18: 0.023950365 | D18: =C18 -> 0.023950365 | E18: =D18 -> 0.023950365 | F18: =E18 -> 0.023950365 | G18: =F18 -> 0.023950365 | H18: =G18 -> 0.023950365 | I18: =H18 -> 0.023950365 | J18: =I18 -> 0.023950365 | L18: Stable
B19: Goodwill + intangibles+other in $ | C19: =C53 -> 83.727 | D19: =C19 -> 83.727 | E19: =D19 -> 83.727 | F19: =E19 -> 83.727 | G19: =F19 -> 83.727 | H19: =G19 -> 83.727 | I19: =H19 -> 83.727 | J19: =I19 -> 83.727 | L19: Stable
B20: Other current assets as % of sales | C20: 0.11871482 | D20: =C20 -> 0.11871482 | E20: =D20 -> 0.11871482 | F20: =E20 -> 0.11871482 | G20: =F20 -> 0.11871482 | H20: =G20 -> 0.11871482 | I20: =H20 -> 0.11871482 | J20: =I20 -> 0.11871482 | L20: Stable
B21: AP as % of COGS | C21: 0.2494471 | D21: =C21 -> 0.2494471 | E21: =D21 -> 0.2494471 | F21: =E21 -> 0.2494471 | G21: =F21 -> 0.2494471 | H21: =G21 -> 0.2494471 | I21: =H21 -> 0.2494471 | J21: =I21 -> 0.2494471 | L21: Stable
B22: Accrued expenses as % of COGS | C22: 0.29091349 | D22: =C22 -> 0.29091349 | E22: =D22 -> 0.29091349 | F22: =E22 -> 0.29091349 | G22: =F22 -> 0.29091349 | H22: =G22 -> 0.29091349 | I22: =H22 -> 0.29091349 | J22: =I22 -> 0.29091349 | L22: Stable
B23: Non-current liabilities - no change | C23: =C60 -> 41.549 | D23: =C23 -> 41.549 | E23: =D23 -> 41.549 | F23: =E23 -> 41.549 | G23: =F23 -> 41.549 | H23: =G23 -> 41.549 | I23: =H23 -> 41.549 | J23: =I23 -> 41.549 | L23: Stable
B24: Other:
B25: Dividends in $ - increase of 5% per year | C25: 0.05 | D25: =C25 -> 0.05 | E25: =D25 -> 0.05 | F25: =E25 -> 0.05 | G25: =F25 -> 0.05 | H25: =G25 -> 0.05 | I25: =H25 -> 0.05 | J25: =I25 -> 0.05
B26: Share repurchases in $ - 80% of net income | C26: 0.8 | D26: 0.8 | E26: =D26 -> 0.8 | F26: =E26 -> 0.8 | G26: =F26 -> 0.8 | H26: =G26 -> 0.8 | I26: =H26 -> 0.8 | J26: =I26 -> 0.8
B27: Additional share repurchases/dividends to use foreign cash ($'B) | D27: 20 | E27: 20 | F27: 10 | G27: 10 | L27: Extra share repurchases
B28: CapEx as % of next year sales | C28: 0.03 | D28: 0.05 | E28: 0.07 | F28: =E28 -> 0.07 | G28: =F28 -> 0.07 | H28: =G28 -> 0.07 | I28: =H28 -> 0.07 | J28: =I28 -> 0.07 | L28: 3% is historical rate, just a bit gorwing because of potential data center needs
B29: Depreciation as % of current year CapEx | C29: 0.8 | D29: =C29 -> 0.8 | E29: =D29 -> 0.8 | F29: =E29 -> 0.8 | G29: =F29 -> 0.8 | H29: =G29 -> 0.8 | I29: =H29 -> 0.8 | J29: =I29 -> 0.8 | L29: Approximately the historical rate
B30: Growth rate - terminal | C30: 0.035
C32: Actual | D32: Forecast | E32: Forecast | F32: Forecast | G32: Forecast | H32: Forecast | I32: Forecast | J32: Forecast
B33: Income statement forecast | C33: =C6 -> 2025 | D33: =D6 -> 2026 | E33: =E6 -> 2027 | F33: =F6 -> 2028 | G33: =G6 -> 2029 | H33: =H6 -> 2030 | I33: =I6 -> 2031 | J33: =J6 -> 2032
B34: Net sales | C34: =IS!V4 -> 416.161 | D34: =C34*(1+D7) -> 487.18848 | E34: =D34*(1+E7) -> 560.26675 | F34: =E34*(1+F7) -> 672.3201 | G34: =F34*(1+G7) -> 773.16812 | H34: =G34*(1+H7) -> 850.48493 | I34: =H34*(1+I7) -> 893.00917 | J34: =I34*(1+J7) -> 928.72954 | L34: See the tab revenue forecast
B35: Cost of sales | C35: =IS!V5 -> -220.96 | D35: =-D34*D8 -> -243.59424 | E35: =-E34*E8 -> -268.92804 | F35: =-F34*F8 -> -309.26725 | G35: =-G34*G8 -> -347.92565 | H35: =-H34*H8 -> -382.71822 | I35: =-I34*I8 -> -401.85413 | J35: =-J34*J8 -> -417.92829
B36: Gross margin | C36: =SUM(C34:C35) -> 195.201 | D36: =SUM(D34:D35) -> 243.59424 | E36: =SUM(E34:E35) -> 291.33871 | F36: =SUM(F34:F35) -> 363.05285 | G36: =SUM(G34:G35) -> 425.24246 | H36: =SUM(H34:H35) -> 467.76671 | I36: =SUM(I34:I35) -> 491.15505 | J36: =SUM(J34:J35) -> 510.80125
B37: Total operating expenses | C37: =IS!V7 -> -62.1 | D37: =-D34*D9 -> -72.698798 | E37: =-E34*E9 -> -83.603618 | F37: =-F34*F9 -> -100.32434 | G37: =-G34*G9 -> -115.37299 | H37: =-H34*H9 -> -126.91029 | I37: =-I34*I9 -> -133.25581 | J37: =-J34*J9 -> -138.58604
B38: Operating income | C38: =SUM(C36:C37) -> 133.101 | D38: =SUM(D36:D37) -> 170.89544 | E38: =SUM(E36:E37) -> 207.73509 | F38: =SUM(F36:F37) -> 262.72851 | G38: =SUM(G36:G37) -> 309.86947 | H38: =SUM(H36:H37) -> 340.85642 | I38: =SUM(I36:I37) -> 357.89924 | J38: =SUM(J36:J37) -> 372.21521
B39: Interest income | D39: =D10*C48 -> 2.89458 | E39: =E10*D48 -> 2.7783193 | F39: =F10*E48 -> 2.2606706 | G39: =G10*F48 -> 2.4354506 | H39: =H10*G48 -> 2.8798354 | I39: =I10*H48 -> 3.9522594 | J39: =J10*I48 -> 5.0258611
B40: Interest expense | D40: =-D11*(C58+C59) -> -4.93285 | E40: =-E11*(D58+D59) -> -4.93285 | F40: =-F11*(E58+E59) -> -4.93285 | G40: =-G11*(F58+F59) -> -4.93285 | H40: =-H11*(G58+G59) -> -4.93285 | I40: =-I11*(H58+H59) -> -4.93285 | J40: =-J11*(I58+I59) -> -4.93285
B41: Income before provision for income taxes | C41: =IS!V12 -> 132.729 | D41: =SUM(D38:D40) -> 168.85717 | E41: =SUM(E38:E40) -> 205.58056 | F41: =SUM(F38:F40) -> 260.05633 | G41: =SUM(G38:G40) -> 307.37207 | H41: =SUM(H38:H40) -> 338.8034 | I41: =SUM(I38:I40) -> 356.91865 | J41: =SUM(J38:J40) -> 372.30822
B42: Provision for income taxes | C42: =IS!V13 -> -20.719 | D42: =-D41*D12 -> -33.771434 | E42: =-E41*E12 -> -41.116112 | F42: =-F41*F12 -> -52.011267 | G42: =-G41*G12 -> -61.474414 | H42: =-H41*H12 -> -67.760681 | I42: =-I41*I12 -> -71.38373 | J42: =-J41*J12 -> -74.461644
B43: Net income | C43: =SUM(C41:C42) -> 112.01 | D43: =SUM(D41:D42) -> 135.08574 | E43: =SUM(E41:E42) -> 164.46445 | F43: =SUM(F41:F42) -> 208.04507 | G43: =SUM(G41:G42) -> 245.89766 | H43: =SUM(H41:H42) -> 271.04272 | I43: =SUM(I41:I42) -> 285.53492 | J43: =SUM(J41:J42) -> 297.84658
...

Sheet Valuation - lower margins
B2: IS and BS forecast, Free Cash Flows and Apple valuation
B3: BASE - estimated value as of November 2025
B5: Assumptions | C5: Actual | D5: Forecast | E5: Forecast | F5: Forecast | G5: Forecast | H5: Forecast | I5: Forecast | J5: Forecast
B6: Income statement | C6: 2025 | D6: 2026 | E6: 2027 | F6: 2028 | G6: 2029 | H6: 2030 | I6: 2031 | J6: 2032
B7: Sales growth | D7: ='Revenue forecast'!D27 -> 0.17067308 | E7: 0.1 | F7: 0.05 | G7: 0.04 | H7: 0.03 | I7: 0.03 | J7: 0.03 | L7: Less demand, competitive pressure
B8: Cost of sales as % sales | C8: ='IS common size'!V6 -> 0.53094836 | D8: 0.51 | E8: 0.52 | F8: 0.55 | G8: 0.6 | H8: =G8 -> 0.6 | I8: =H8 -> 0.6 | J8: =I8 -> 0.6 | L8: Higher costs - maybe tariffs
B9: Ops expenses as % of sales | C9: ='IS common size'!V8 -> 0.14922109 | D9: =C9 -> 0.14922109 | E9: =D9 -> 0.14922109 | F9: =E9 -> 0.14922109 | G9: =F9 -> 0.14922109 | H9: =G9 -> 0.14922109 | I9: =H9 -> 0.14922109 | J9: =I9 -> 0.14922109 | L9: Stable
B10: Interest income | C10: 0.03 | D10: =C10 -> 0.03 | E10: 0.04 | F10: =E10 -> 0.04 | G10: =F10 -> 0.04 | H10: =G10 -> 0.04 | I10: =H10 -> 0.04 | J10: =I10 -> 0.04 | L10: Increasing at the interest rates increase
B11: Interest expense | C11: 0.05 | D11: =C11 -> 0.05 | E11: 0.05 | F11: =E11 -> 0.05 | G11: =F11 -> 0.05 | H11: =G11 -> 0.05 | I11: =H11 -> 0.05 | J11: =I11 -> 0.05 | L11: Increasing at the interest rates increase
B12: Tax rate as % of pretax income (going down) | C12: 0.2 | D12: =C12 -> 0.2 | E12: =D12 -> 0.2 | F12: =E12 -> 0.2 | G12: =F12 -> 0.2 | H12: =G12 -> 0.2 | I12: =H12 -> 0.2 | J12: =I12 -> 0.2 | L12: Based on the new tax rules
B13: Balance sheet
B14: Cash - stable in $ | C14: =C47 -> 35.934 | D14: =C14 -> 35.934 | E14: =D14 -> 35.934 | F14: =E14 -> 35.934 | G14: =F14 -> 35.934 | H14: =G14 -> 35.934 | I14: =H14 -> 35.934 | J14: =I14 -> 35.934 | L14: Stable
B15: ST debt - stable | C15: =C58 -> 20.329 | D15: =C15 -> 20.329 | E15: =D15 -> 20.329 | F15: =E15 -> 20.329 | G15: =F15 -> 20.329 | H15: =G15 -> 20.329 | I15: =H15 -> 20.329 | J15: =I15 -> 20.329 | L15: Stable
B16: LT debt - stable | C16: =C59 -> 78.328 | D16: =C16 -> 78.328 | E16: =D16 -> 78.328 | F16: =E16 -> 78.328 | G16: =F16 -> 78.328 | H16: =G16 -> 78.328 | I16: =H16 -> 78.328 | J16: =I16 -> 78.328 | L16: Stable
B17: AR as % of sales | C17: 0.058721746 | D17: =C17 -> 0.058721746 | E17: =D17 -> 0.058721746 | F17: =E17 -> 0.058721746 | G17: =F17 -> 0.058721746 | H17: =G17 -> 0.058721746 | I17: =H17 -> 0.058721746 | J17: =I17 -> 0.058721746 | L17: Stable
B18: Inventory as % of COGS | C18: 0.023950365 | D18: =C18 -> 0.023950365 | E18: =D18 -> 0.023950365 | F18: =E18 -> 0.023950365 | G18: =F18 -> 0.023950365 | H18: =G18 -> 0.023950365 | I18: =H18 -> 0.023950365 | J18: =I18 -> 0.023950365 | L18: Stable
B19: Goodwill + intangibles+other in $ | C19: =C53 -> 83.727 | D19: =C19 -> 83.727 | E19: =D19 -> 83.727 | F19: =E19 -> 83.727 | G19: =F19 -> 83.727 | H19: =G19 -> 83.727 | I19: =H19 -> 83.727 | J19: =I19 -> 83.727 | L19: Stable
B20: Other current assets as % of sales | C20: 0.11871482 | D20: =C20 -> 0.11871482 | E20: =D20 -> 0.11871482 | F20: =E20 -> 0.11871482 | G20: =F20 -> 0.11871482 | H20: =G20 -> 0.11871482 | I20: =H20 -> 0.11871482 | J20: =I20 -> 0.11871482 | L20: Stable
B21: AP as % of COGS | C21: 0.2494471 | D21: =C21 -> 0.2494471 | E21: =D21 -> 0.2494471 | F21: =E21 -> 0.2494471 | G21: =F21 -> 0.2494471 | H21: =G21 -> 0.2494471 | I21: =H21 -> 0.2494471 | J21: =I21 -> 0.2494471 | L21: Stable
B22: Accrued expenses as % of COGS | C22: 0.29091349 | D22: =C22 -> 0.29091349 | E22: =D22 -> 0.29091349 | F22: =E22 -> 0.29091349 | G22: =F22 -> 0.29091349 | H22: =G22 -> 0.29091349 | I22: =H22 -> 0.29091349 | J22: =I22 -> 0.29091349 | L22: Stable
B23: Non-current liabilities - no change | C23: =C60 -> 41.549 | D23: =C23 -> 41.549 | E23: =D23 -> 41.549 | F23: =E23 -> 41.549 | G23: =F23 -> 41.549 | H23: =G23 -> 41.549 | I23: =H23 -> 41.549 | J23: =I23 -> 41.549 | L23: Stable
B24: Other:
B25: Dividends in $ - increase of 5% per year | C25: 0.05 | D25: =C25 -> 0.05 | E25: =D25 -> 0.05 | F25: =E25 -> 0.05 | G25: =F25 -> 0.05 | H25: =G25 -> 0.05 | I25: =H25 -> 0.05 | J25: =I25 -> 0.05
B26: Share repurchases in $ - 80% of net income | C26: 0.8 | D26: 0.8 | E26: =D26 -> 0.8 | F26: =E26 -> 0.8 | G26: =F26 -> 0.8 | H26: =G26 -> 0.8 | I26: =H26 -> 0.8 | J26: =I26 -> 0.8
B27: Additional share repurchases/dividends to use foreign cash ($'B) | D27: 20 | E27: 20 | F27: 10 | G27: 10 | L27: Extra share repurchases
B28: CapEx as % of next year sales | C28: 0.03 | D28: 0.05 | E28: 0.07 | F28: =E28 -> 0.07 | G28: =F28 -> 0.07 | H28: =G28 -> 0.07 | I28: =H28 -> 0.07 | J28: =I28 -> 0.07 | L28: 3% is historical rate, just a bit gorwing because of potential data center needs
B29: Depreciation as % of current year CapEx | C29: 0.8 | D29: =C29 -> 0.8 | E29: =D29 -> 0.8 | F29: =E29 -> 0.8 | G29: =F29 -> 0.8 | H29: =G29 -> 0.8 | I29: =H29 -> 0.8 | J29: =I29 -> 0.8 | L29: Approximately the historical rate
B30: Growth rate - terminal | C30: 0.035
C32: Actual | D32: Forecast | E32: Forecast | F32: Forecast | G32: Forecast | H32: Forecast | I32: Forecast | J32: Forecast
B33: Income statement forecast | C33: =C6 -> 2025 | D33: =D6 -> 2026 | E33: =E6 -> 2027 | F33: =F6 -> 2028 | G33: =G6 -> 2029 | H33: =H6 -> 2030 | I33: =I6 -> 2031 | J33: =J6 -> 2032
B34: Net sales | C34: =IS!V4 -> 416.161 | D34: =C34*(1+D7) -> 487.18848 | E34: =D34*(1+E7) -> 535.90733 | F34: =E34*(1+F7) -> 562.70269 | G34: =F34*(1+G7) -> 585.2108 | H34: =G34*(1+H7) -> 602.76712 | I34: =H34*(1+I7) -> 620.85014 | J34: =I34*(1+J7) -> 639.47564 | L34: See the tab revenue forecast
B35: Cost of sales | C35: =IS!V5 -> -220.96 | D35: =-D34*D8 -> -248.46612 | E35: =-E34*E8 -> -278.67181 | F35: =-F34*F8 -> -309.48648 | G35: =-G34*G8 -> -351.12648 | H35: =-H34*H8 -> -361.66027 | I35: =-I34*I8 -> -372.51008 | J35: =-J34*J8 -> -383.68539
B36: Gross margin | C36: =SUM(C34:C35) -> 195.201 | D36: =SUM(D34:D35) -> 238.72235 | E36: =SUM(E34:E35) -> 257.23552 | F36: =SUM(F34:F35) -> 253.21621 | G36: =SUM(G34:G35) -> 234.08432 | H36: =SUM(H34:H35) -> 241.10685 | I36: =SUM(I34:I35) -> 248.34006 | J36: =SUM(J34:J35) -> 255.79026
B37: Total operating expenses | C37: =IS!V7 -> -62.1 | D37: =-D34*D9 -> -72.698798 | E37: =-E34*E9 -> -79.968678 | F37: =-F34*F9 -> -83.967112 | G37: =-G34*G9 -> -87.325796 | H37: =-H34*H9 -> -89.94557 | I37: =-I34*I9 -> -92.643937 | J37: =-J34*J9 -> -95.423255
B38: Operating income | C38: =SUM(C36:C37) -> 133.101 | D38: =SUM(D36:D37) -> 166.02356 | E38: =SUM(E36:E37) -> 177.26684 | F38: =SUM(F36:F37) -> 169.2491 | G38: =SUM(G36:G37) -> 146.75852 | H38: =SUM(H36:H37) -> 151.16128 | I38: =SUM(I36:I37) -> 155.69612 | J38: =SUM(J36:J37) -> 160.367
B39: Interest income | D39: =D10*C48 -> 2.89458 | E39: =E10*D48 -> 2.8575186 | F39: =F10*E48 -> 2.4802915 | G39: =G10*F48 -> 2.5718377 | H39: =H10*G48 -> 2.7295108 | I39: =I10*H48 -> 2.6623816 | J39: =J10*I48 -> 2.5883468
B40: Interest expense | D40: =-D11*(C58+C59) -> -4.93285 | E40: =-E11*(D58+D59) -> -4.93285 | F40: =-F11*(E58+E59) -> -4.93285 | G40: =-G11*(F58+F59) -> -4.93285 | H40: =-H11*(G58+G59) -> -4.93285 | I40: =-I11*(H58+H59) -> -4.93285 | J40: =-J11*(I58+I59) -> -4.93285
B41: Income before provision for income taxes | C41: =IS!V12 -> 132.729 | D41: =SUM(D38:D40) -> 163.98529 | E41: =SUM(E38:E40) -> 175.19151 | F41: =SUM(F38:F40) -> 166.79654 | G41: =SUM(G38:G40) -> 144.39751 | H41: =SUM(H38:H40) -> 148.95794 | I41: =SUM(I38:I40) -> 153.42565 | J41: =SUM(J38:J40) -> 158.0225
B42: Provision for income taxes | C42: =IS!V13 -> -20.719 | D42: =-D41*D12 -> -32.797057 | E42: =-E41*E12 -> -35.038301 | F42: =-F41*F12 -> -33.359308 | G42: =-G41*G12 -> -28.879502 | H42: =-H41*H12 -> -29.791588 | I42: =-I41*I12 -> -30.68513 | J42: =-J41*J12 -> -31.6045
B43: Net income | C43: =SUM(C41:C42) -> 112.01 | D43: =SUM(D41:D42) -> 131.18823 | E43: =SUM(E41:E42) -> 140.15321 | F43: =SUM(F41:F42) -> 133.43723 | G43: =SUM(G41:G42) -> 115.51801 | H43: =SUM(H41:H42) -> 119.16635 | I43: =SUM(I41:I42) -> 122.74052 | J43: =SUM(J41:J42) -> 126.418
...

Sheet Valuation - base - 2026
B2: IS and BS forecast, Free Cash Flows and Apple valuation
B3: BASE - estimated value as of September 2025
B5: Assumptions | C5: ='Valuation - base'!C5 -> Actual | D5: ='Valuation - base'!D5 -> Forecast | E5: ='Valuation - base'!E5 -> Forecast | F5: ='Valuation - base'!F5 -> Forecast | G5: ='Valuation - base'!G5 -> Forecast | H5: ='Valuation - base'!H5 -> Forecast | I5: ='Valuation - base'!I5 -> Forecast | J5: ='Valuation - base'!J5 -> Forecast
B6: Income statement | C6: ='Valuation - base'!C6 -> 2025 | D6: ='Valuation - base'!D6 -> 2026 | E6: ='Valuation - base'!E6 -> 2027 | F6: ='Valuation - base'!F6 -> 2028 | G6: ='Valuation - base'!G6 -> 2029 | H6: ='Valuation - base'!H6 -> 2030 | I6: ='Valuation - base'!I6 -> 2031 | J6: ='Valuation - base'!J6 -> 2032
B7: Sales growth | D7: ='Valuation - base'!D7 -> 0.17067308 | E7: ='Valuation - base'!E7 -> 0.11967146 | F7: ='Valuation - base'!F7 -> 0.07918684 | G7: ='Valuation - base'!G7 -> 0.07 | H7: ='Valuation - base'!H7 -> 0.06 | I7: ='Valuation - base'!I7 -> 0.05 | J7: ='Valuation - base'!J7 -> 0.04 | L7: See the tab revenue forecast
B8: Cost of sales as % sales | C8: ='Valuation - base'!C8 -> 0.53094836 | D8: ='Valuation - base'!D8 -> 0.51 | E8: ='Valuation - base'!E8 -> 0.49 | F8: ='Valuation - base'!F8 -> 0.47 | G8: ='Valuation - base'!G8 -> 0.47 | H8: ='Valuation - base'!H8 -> 0.47 | I8: ='Valuation - base'!I8 -> 0.47 | J8: ='Valuation - base'!J8 -> 0.47 | L8: Going down sligthly as a result of higher % of services as % of sales
B9: Ops expenses as % of sales | C9: ='Valuation - base'!C9 -> 0.14922109 | D9: ='Valuation - base'!D9 -> 0.14922109 | E9: ='Valuation - base'!E9 -> 0.14922109 | F9: ='Valuation - base'!F9 -> 0.14922109 | G9: ='Valuation - base'!G9 -> 0.14922109 | H9: ='Valuation - base'!H9 -> 0.14922109 | I9: ='Valuation - base'!I9 -> 0.14922109 | J9: ='Valuation - base'!J9 -> 0.14922109 | L9: Stable
B10: Interest income | C10: ='Valuation - base'!C10 -> 0.03 | D10: ='Valuation - base'!D10 -> 0.03 | E10: ='Valuation - base'!E10 -> 0.04 | F10: ='Valuation - base'!F10 -> 0.04 | G10: ='Valuation - base'!G10 -> 0.04 | H10: ='Valuation - base'!H10 -> 0.04 | I10: ='Valuation - base'!I10 -> 0.04 | J10: ='Valuation - base'!J10 -> 0.04 | L10: Increasing at the interest rates increase
B11: Interest expense | C11: ='Valuation - base'!C11 -> 0.05 | D11: ='Valuation - base'!D11 -> 0.05 | E11: ='Valuation - base'!E11 -> 0.05 | F11: ='Valuation - base'!F11 -> 0.05 | G11: ='Valuation - base'!G11 -> 0.05 | H11: ='Valuation - base'!H11 -> 0.05 | I11: ='Valuation - base'!I11 -> 0.05 | J11: ='Valuation - base'!J11 -> 0.05 | L11: Increasing at the interest rates increase
B12: Tax rate as % of pretax income (going down) | C12: ='Valuation - base'!C12 -> 0.2 | D12: ='Valuation - base'!D12 -> 0.2 | E12: ='Valuation - base'!E12 -> 0.2 | F12: ='Valuation - base'!F12 -> 0.2 | G12: ='Valuation - base'!G12 -> 0.2 | H12: ='Valuation - base'!H12 -> 0.2 | I12: ='Valuation - base'!I12 -> 0.2 | J12: ='Valuation - base'!J12 -> 0.2 | L12: Based on the new tax rules
B13: Balance sheet
B14: Cash - stable in $ | C14: ='Valuation - base'!C14 -> 35.934 | D14: ='Valuation - base'!D14 -> 35.934 | E14: ='Valuation - base'!E14 -> 35.934 | F14: ='Valuation - base'!F14 -> 35.934 | G14: ='Valuation - base'!G14 -> 35.934 | H14: ='Valuation - base'!H14 -> 35.934 | I14: ='Valuation - base'!I14 -> 35.934 | J14: ='Valuation - base'!J14 -> 35.934 | L14: Stable
B15: ST debt - stable | C15: ='Valuation - base'!C15 -> 20.329 | D15: ='Valuation - base'!D15 -> 20.329 | E15: ='Valuation - base'!E15 -> 20.329 | F15: ='Valuation - base'!F15 -> 20.329 | G15: ='Valuation - base'!G15 -> 20.329 | H15: ='Valuation - base'!H15 -> 20.329 | I15: ='Valuation - base'!I15 -> 20.329 | J15: ='Valuation - base'!J15 -> 20.329 | L15: Stable
B16: LT debt - stable | C16: ='Valuation - base'!C16 -> 78.328 | D16: ='Valuation - base'!D16 -> 78.328 | E16: ='Valuation - base'!E16 -> 78.328 | F16: ='Valuation - base'!F16 -> 78.328 | G16: ='Valuation - base'!G16 -> 78.328 | H16: ='Valuation - base'!H16 -> 78.328 | I16: ='Valuation - base'!I16 -> 78.328 | J16: ='Valuation - base'!J16 -> 78.328 | L16: Stable
B17: AR as % of sales | C17: ='Valuation - base'!C17 -> 0.058721746 | D17: ='Valuation - base'!D17 -> 0.058721746 | E17: ='Valuation - base'!E17 -> 0.058721746 | F17: ='Valuation - base'!F17 -> 0.058721746 | G17: ='Valuation - base'!G17 -> 0.058721746 | H17: ='Valuation - base'!H17 -> 0.058721746 | I17: ='Valuation - base'!I17 -> 0.058721746 | J17: ='Valuation - base'!J17 -> 0.058721746 | L17: Stable
B18: Inventory as % of COGS | C18: ='Valuation - base'!C18 -> 0.023950365 | D18: ='Valuation - base'!D18 -> 0.023950365 | E18: ='Valuation - base'!E18 -> 0.023950365 | F18: ='Valuation - base'!F18 -> 0.023950365 | G18: ='Valuation - base'!G18 -> 0.023950365 | H18: ='Valuation - base'!H18 -> 0.023950365 | I18: ='Valuation - base'!I18 -> 0.023950365 | J18: ='Valuation - base'!J18 -> 0.023950365 | L18: Stable
B19: Goodwill + intangibles+other in $ | C19: ='Valuation - base'!C19 -> 83.727 | D19: ='Valuation - base'!D19 -> 83.727 | E19: ='Valuation - base'!E19 -> 83.727 | F19: ='Valuation - base'!F19 -> 83.727 | G19: ='Valuation - base'!G19 -> 83.727 | H19: ='Valuation - base'!H19 -> 83.727 | I19: ='Valuation - base'!I19 -> 83.727 | J19: ='Valuation - base'!J19 -> 83.727 | L19: Stable
B20: Other current assets as % of sales | C20: ='Valuation - base'!C20 -> 0.11871482 | D20: ='Valuation - base'!D20 -> 0.11871482 | E20: ='Valuation - base'!E20 -> 0.11871482 | F20: ='Valuation - base'!F20 -> 0.11871482 | G20: ='Valuation - base'!G20 -> 0.11871482 | H20: ='Valuation - base'!H20 -> 0.11871482 | I20: ='Valuation - base'!I20 -> 0.11871482 | J20: ='Valuation - base'!J20 -> 0.11871482 | L20: Stable
B21: AP as % of COGS | C21: ='Valuation - base'!C21 -> 0.2494471 | D21: ='Valuation - base'!D21 -> 0.2494471 | E21: ='Valuation - base'!E21 -> 0.2494471 | F21: ='Valuation - base'!F21 -> 0.2494471 | G21: ='Valuation - base'!G21 -> 0.2494471 | H21: ='Valuation - base'!H21 -> 0.2494471 | I21: ='Valuation - base'!I21 -> 0.2494471 | J21: ='Valuation - base'!J21 -> 0.2494471 | L21: Stable
B22: Accrued expenses as % of COGS | C22: ='Valuation - base'!C22 -> 0.29091349 | D22: ='Valuation - base'!D22 -> 0.29091349 | E22: ='Valuation - base'!E22 -> 0.29091349 | F22: ='Valuation - base'!F22 -> 0.29091349 | G22: ='Valuation - base'!G22 -> 0.29091349 | H22: ='Valuation - base'!H22 -> 0.29091349 | I22: ='Valuation - base'!I22 -> 0.29091349 | J22: ='Valuation - base'!J22 -> 0.29091349 | L22: Stable
B23: Non-current liabilities - no change | C23: ='Valuation - base'!C23 -> 41.549 | D23: ='Valuation - base'!D23 -> 41.549 | E23: ='Valuation - base'!E23 -> 41.549 | F23: ='Valuation - base'!F23 -> 41.549 | G23: ='Valuation - base'!G23 -> 41.549 | H23: ='Valuation - base'!H23 -> 41.549 | I23: ='Valuation - base'!I23 -> 41.549 | J23: ='Valuation - base'!J23 -> 41.549 | L23: Stable
B24: Other:
B25: Dividends in $ - increase of 5% per year | C25: ='Valuation - base'!C25 -> 0.05 | D25: ='Valuation - base'!D25 -> 0.05 | E25: ='Valuation - base'!E25 -> 0.05 | F25: ='Valuation - base'!F25 -> 0.05 | G25: ='Valuation - base'!G25 -> 0.05 | H25: ='Valuation - base'!H25 -> 0.05 | I25: ='Valuation - base'!I25 -> 0.05 | J25: ='Valuation - base'!J25 -> 0.05
B26: Share repurchases in $ - 70% of net income | C26: ='Valuation - base'!C26 -> 0.8 | D26: ='Valuation - base'!D26 -> 0.8 | E26: ='Valuation - base'!E26 -> 0.8 | F26: ='Valuation - base'!F26 -> 0.8 | G26: ='Valuation - base'!G26 -> 0.8 | H26: ='Valuation - base'!H26 -> 0.8 | I26: ='Valuation - base'!I26 -> 0.8 | J26: ='Valuation - base'!J26 -> 0.8
B27: Additional share repurchases/dividends to use foreign cash ($'B) | D27: ='Valuation - base'!D27 -> 20 | E27: ='Valuation - base'!E27 -> 20 | F27: ='Valuation - base'!F27 -> 10 | G27: ='Valuation - base'!G27 -> 10 | L27: Extra share repurchases
B28: CapEx as % of next year sales | C28: ='Valuation - base'!C28 -> 0.03 | D28: ='Valuation - base'!D28 -> 0.05 | E28: ='Valuation - base'!E28 -> 0.07 | F28: ='Valuation - base'!F28 -> 0.07 | G28: ='Valuation - base'!G28 -> 0.07 | H28: ='Valuation - base'!H28 -> 0.07 | I28: ='Valuation - base'!I28 -> 0.07 | J28: ='Valuation - base'!J28 -> 0.07 | L28: Approximately the historical rate, stable business
B29: Depreciation as % of current year CapEx | C29: ='Valuation - base'!C29 -> 0.8 | D29: ='Valuation - base'!D29 -> 0.8 | E29: ='Valuation - base'!E29 -> 0.8 | F29: ='Valuation - base'!F29 -> 0.8 | G29: ='Valuation - base'!G29 -> 0.8 | H29: ='Valuation - base'!H29 -> 0.8 | I29: ='Valuation - base'!I29 -> 0.8 | J29: ='Valuation - base'!J29 -> 0.8 | L29: Approximately the historical rate
B30: Growth rate - terminal | C30: ='Valuation - base'!C30 -> 0.035
C32: ='Valuation - base'!C32 -> Actual | D32: ='Valuation - base'!D32 -> Forecast | E32: ='Valuation - base'!E32 -> Forecast | F32: ='Valuation - base'!F32 -> Forecast | G32: ='Valuation - base'!G32 -> Forecast | H32: ='Valuation - base'!H32 -> Forecast | I32: ='Valuation - base'!I32 -> Forecast | J32: ='Valuation - base'!J32 -> Forecast
B33: Income statement forecast | C33: ='Valuation - base'!C33 -> 2025 | D33: ='Valuation - base'!D33 -> 2026 | E33: ='Valuation - base'!E33 -> 2027 | F33: ='Valuation - base'!F33 -> 2028 | G33: ='Valuation - base'!G33 -> 2029 | H33: ='Valuation - base'!H33 -> 2030 | I33: ='Valuation - base'!I33 -> 2031 | J33: ='Valuation - base'!J33 -> 2032
B34: Net sales | C34: ='Valuation - base'!C34 -> 416.161 | D34: ='Valuation - base'!D34 -> 487 | E34: ='Valuation - base'!E34 -> 545.28 | F34: ='Valuation - base'!F34 -> 588.459 | G34: ='Valuation - base'!G34 -> 629.65113 | H34: ='Valuation - base'!H34 -> 667.4302 | I34: ='Valuation - base'!I34 -> 700.80171 | J34: ='Valuation - base'!J34 -> 728.83378 | L34: See the tab revenue forecast
B35: Cost of sales | C35: ='Valuation - base'!C35 -> -220.96 | D35: ='Valuation - base'!D35 -> -248.37 | E35: ='Valuation - base'!E35 -> -267.1872 | F35: ='Valuation - base'!F35 -> -276.57573 | G35: ='Valuation - base'!G35 -> -295.93603 | H35: ='Valuation - base'!H35 -> -313.69219 | I35: ='Valuation - base'!I35 -> -329.3768 | J35: ='Valuation - base'!J35 -> -342.55187
B36: Gross margin | C36: ='Valuation - base'!C36 -> 195.201 | D36: ='Valuation - base'!D36 -> 238.63 | E36: ='Valuation - base'!E36 -> 278.0928 | F36: ='Valuation - base'!F36 -> 311.88327 | G36: ='Valuation - base'!G36 -> 333.7151 | H36: ='Valuation - base'!H36 -> 353.738 | I36: ='Valuation - base'!I36 -> 371.42491 | J36: ='Valuation - base'!J36 -> 386.2819
B37: Total operating expenses | C37: ='Valuation - base'!C37 -> -62.1 | D37: ='Valuation - base'!D37 -> -72.670673 | E37: ='Valuation - base'!E37 -> -81.367279 | F37: ='Valuation - base'!F37 -> -87.810496 | G37: ='Valuation - base'!G37 -> -93.957231 | H37: ='Valuation - base'!H37 -> -99.594665 | I37: ='Valuation - base'!I37 -> -104.5744 | J37: ='Valuation - base'!J37 -> -108.75737
B38: Operating income | C38: ='Valuation - base'!C38 -> 133.101 | D38: ='Valuation - base'!D38 -> 165.95933 | E38: ='Valuation - base'!E38 -> 196.72552 | F38: ='Valuation - base'!F38 -> 224.07277 | G38: ='Valuation - base'!G38 -> 239.75787 | H38: ='Valuation - base'!H38 -> 254.14334 | I38: ='Valuation - base'!I38 -> 266.85051 | J38: ='Valuation - base'!J38 -> 277.52453
B39: Interest income | C39: ='Valuation - base'!C39 -> 0 | D39: ='Valuation - base'!D39 -> 2.89458 | E39: ='Valuation - base'!E39 -> 2.8527106 | F39: ='Valuation - base'!F39 -> 2.2824597 | G39: ='Valuation - base'!G39 -> 2.1398552 | H39: ='Valuation - base'!H39 -> 2.2609205 | I39: ='Valuation - base'!I39 -> 2.8107626 | J39: ='Valuation - base'!J39 -> 3.3956528
B40: Interest expense | C40: ='Valuation - base'!C40 -> 0 | D40: ='Valuation - base'!D40 -> -4.93285 | E40: ='Valuation - base'!E40 -> -4.93285 | F40: ='Valuation - base'!F40 -> -4.93285 | G40: ='Valuation - base'!G40 -> -4.93285 | H40: ='Valuation - base'!H40 -> -4.93285 | I40: ='Valuation - base'!I40 -> -4.93285 | J40: ='Valuation - base'!J40 -> -4.93285
B41: Income before provision for income taxes | C41: ='Valuation - base'!C41 -> 132.729 | D41: ='Valuation - base'!D41 -> 163.92106 | E41: ='Valuation - base'!E41 -> 194.64538 | F41: ='Valuation - base'!F41 -> 221.42238 | G41: ='Valuation - base'!G41 -> 236.96487 | H41: ='Valuation - base'!H41 -> 251.47141 | I41: ='Valuation - base'!I41 -> 264.72842 | J41: ='Valuation - base'!J41 -> 275.98733
B42: Provision for income taxes | C42: ='Valuation - base'!C42 -> -20.719 | D42: ='Valuation - base'!D42 -> -32.784211 | E42: ='Valuation - base'!E42 -> -38.929076 | F42: ='Valuation - base'!F42 -> -44.284477 | G42: ='Valuation - base'!G42 -> -47.392975 | H42: ='Valuation - base'!H42 -> -50.294282 | I42: ='Valuation - base'!I42 -> -52.945684 | J42: ='Valuation - base'!J42 -> -55.197466
B43: Net income | C43: ='Valuation - base'!C43 -> 112.01 | D43: ='Valuation - base'!D43 -> 131.13685 | E43: ='Valuation - base'!E43 -> 155.71631 | F43: ='Valuation - base'!F43 -> 177.13791 | G43: ='Valuation - base'!G43 -> 189.5719 | H43: ='Valuation - base'!H43 -> 201.17713 | I43: ='Valuation - base'!I43 -> 211.78274 | J43: ='Valuation - base'!J43 -> 220.78986
...

Sheet cost of capital
B2: Cost of capital
B3: Assumes that the weight of debt in the capital structure will remain stable going forward
B5: Inputs | E5: Comment
B6: Cost of debt | C6: 0.03 | E6: From Apple 10K (approximate)
B7: Tax rate | C7: 0.21 | E7: Interest payments are in the US
B8: 10y UST | C8: 0.025 | E8: Estimate - long-term
B9: Market risk premium | C9: 0.06 | E9: Estimate - long-term
B10: Beta Apple | C10: 1.1 | E10: From Yahoo Finance
B11: Beta Apple - assuming similar leverage | C11: 1.1 | E11: Estimate - similar leverage going forward
B12: Shares Sept 2023 | C12: 14.8 | E12: Yahoo Finance
B14: Debt value Sept 2025 | C14: 100 | E14: From 2025 BS
B15: Equity value November 2025 | C15: 4000 | E15: Market cap approximation
B16: Gross debt weight November 2025 | C16: =C14/(C14+C15) -> 0.024390244 | E16: Used market cap and current gross debt
B17: Permanent debt weight - estimate | C17: 0.15 | E17: Estimate
B19: Cost of capital calculation
B20: Cost of equity | C20: =C8+C9*C11 -> 0.091 | E20: CAPM
B21: After-tax cost of debt | C21: =C6*(1-C7) -> 0.0237
B22: WACC | C22: =C21*C17+(1-C17)*C20 -> 0.080905

Sheet IS
B2: Income Statement - As Reported
C3: Sep '06 | D3: Sep '07 | E3: Sep '08 | F3: Sep '09 | G3: Sep '10 | H3: Sep '11 | I3: Sep '12 | J3: Sep '13 | K3: Sep '14 | L3: Sep '15 | M3: Sep '16 | N3: Sep '17 | O3: Sep '18 | P3: Sep '19 | Q3: Sep '20 | R3: Sep '21 | S3: Sep '22 | T3: Sep '23 | U3: Sep '24 | V3: Sep '25
B4: Net sales | C4: 19.315 | D4: 24.006 | E4: 37.491 | F4: 42.905 | G4: 65.225 | H4: 108.249 | I4: 156.508 | J4: 170.91 | K4: 182.795 | L4: 233.715 | M4: 215.639 | N4: 229.234 | O4: 265.595 | P4: 260.174 | Q4: 274.515 | R4: 365.817 | S4: 394 | T4: 383 | U4: 391 | V4: 416.161
B5: Cost of sales | C5: -13.717 | D5: -15.852 | E5: -24.294 | F5: -25.683 | G5: -39.541 | H5: -64.431 | I5: -87.846 | J5: -106.606 | K5: -112.258 | L5: -140.089 | M5: -131.376 | N5: -141.048 | O5: -163.756 | P5: -161.782 | Q5: -169.559 | R5: -212.981 | S5: -224 | T5: -214 | U5: -210 | V5: -220.96
B6: Gross margin | C6: 5.598 | D6: 8.154 | E6: 13.197 | F6: 17.222 | G6: 25.684 | H6: 43.818 | I6: 68.662 | J6: 64.304 | K6: 70.537 | L6: 93.626 | M6: 84.263 | N6: 88.186 | O6: 101.839 | P6: 98.392 | Q6: 104.956 | R6: 152.836 | S6: 171 | T6: 169 | U6: =SUM(U4:U5) -> 181 | V6: 195.201
B7: Total operating expenses | C7: -3.145 | D7: -3.745 | E7: -4.87 | F7: -5.482 | G7: -7.299 | H7: -10.028 | I7: -13.421 | J7: -15.305 | K7: -18.034 | L7: -22.396 | M7: -24.239 | N7: -26.842 | O7: -30.941 | P7: -34.462 | Q7: =SUM(Q8:Q9) -> -38.668 | R7: -43.887 | S7: -51 | T7: -55 | U7: -58 | V7: -62.1
B8: Research and development | C8: -0.712 | D8: -0.782 | E8: -1.109 | F8: -1.333 | G8: -1.782 | H8: -2.429 | I8: -3.381 | J8: -4.475 | K8: -6.041 | L8: -8.067 | M8: -10.045 | N8: -11.581 | O8: -14.236 | P8: -16.217 | Q8: -18.752 | R8: -21.914 | S8: -26 | T8: -30 | U8: -31 | V8: -34.55
B9: Selling, general and administrative | C9: -2.433 | D9: -2.963 | E9: -3.761 | F9: -4.149 | G9: -5.517 | H9: -7.599 | I9: -10.04 | J9: -10.83 | K9: -11.993 | L9: -14.329 | M9: -14.194 | N9: -15.261 | O9: -16.705 | P9: -18.245 | Q9: -19.916 | R9: -21.973 | S9: -25 | T9: -25 | U9: -26 | V9: -27.601
B10: Operating income | C10: 2.453 | D10: 4.409 | E10: 8.327 | F10: 11.74 | G10: 18.385 | H10: 33.79 | I10: 55.241 | J10: 48.999 | K10: 52.503 | L10: 71.23 | M10: 60.024 | N10: 61.344 | O10: 70.898 | P10: 63.93 | Q10: =Q6+Q7 -> 66.288 | R10: 108.949 | S10: 119.4 | T10: 114 | U10: 123.2 | V10: 133.05
B11: Other income / expense, net | C11: 0.365 | D11: 0.599 | E11: 0.62 | F11: 0.326 | G11: 0.155 | H11: 0.415 | I11: 0.522 | J11: 1.156 | K11: 0.98 | L11: 1.285 | M11: 1.348 | N11: 2.745 | O11: 2.005 | P11: 1.807 | Q11: 0.803 | R11: 0.258 | S11: -0.3 | T11: -0.5 | U11: 0.3 | V11: -0.321
B12: Income before provision for income taxes | C12: 2.818 | D12: 5.008 | E12: 8.947 | F12: 12.066 | G12: 18.54 | H12: 34.205 | I12: 55.763 | J12: 50.155 | K12: 53.483 | L12: 72.515 | M12: 61.372 | N12: 64.089 | O12: 72.903 | P12: 65.737 | Q12: =Q10+Q11 -> 67.091 | R12: 109.207 | S12: 119.1 | T12: 114 | U12: =SUM(U10:U11) -> 123.5 | V12: 132.729
B13: Provision for income taxes | C13: -0.829 | D13: -1.512 | E13: -2.828 | F13: -3.831 | G13: -4.527 | H13: -8.283 | I13: -14.03 | J13: -13.118 | K13: -13.973 | L13: -19.121 | M13: -15.685 | N13: -15.738 | O13: -13.372 | P13: -10.481 | Q13: -9.68 | R13: -14.527 | S13: -19.3 | T13: -18 | U13: -30 | V13: -20.719
B14: Net income | C14: 1.989 | D14: 3.496 | E14: 6.119 | F14: 8.235 | G14: 14.013 | H14: 25.922 | I14: 41.733 | J14: 37.037 | K14: 39.51 | L14: 53.394 | M14: 45.687 | N14: 48.351 | O14: 59.531 | P14: 55.256 | Q14: =SUM(Q12:Q13) -> 57.411 | R14: 94.68 | S14: 100 | T14: 97 | U14: 93.7 | V14: 112.01
B16: Interest expense | C16: 0 | D16: 0 | E16: 0 | F16: 0 | G16: 0 | H16: 0 | I16: 0 | J16: 0.136 | K16: 0.384 | L16: 0.733 | M16: 1.46 | N16: 2.3 | O16: 3.24 | P16: 3.6 | Q16: 2.9 | R16: 2.6 | S16: 2.9 | T16: 4 | U16: 4 | V16: 4
B17: Dividends | C17: 0 | D17: 0 | E17: 0 | F17: 0 | G17: 0 | H17: 0 | I17: 2.488 | J17: 10.564 | K17: 11.126 | L17: 11.561 | M17: 12.2 | N17: 12.8 | O17: 13.7 | P17: 14.12 | Q17: 14.08 | R17: 14.5 | S17: 14.8 | T17: 15 | U17: 15 | V17: 15

Sheet IS common size
B2: Income Statement - As Reported - common size
C4: Sep '06 | D4: Sep '07 | E4: Sep '08 | F4: Sep '09 | G4: Sep '10 | H4: Sep '11 | I4: Sep '12 | J4: Sep '13 | K4: Sep '14 | L4: Sep '15 | M4: Sep '16 | N4: Sep '17 | O4: Sep '18 | P4: Sep '19 | Q4: =IS!Q3 -> Sep '20 | R4: =IS!R3 -> Sep '21 | S4: =IS!S3 -> Sep '22 | T4: =IS!T3 -> Sep '23 | U4: =IS!U3 -> Sep '24 | V4: =IS!V3 -> Sep '25
B5: Net sales in $'B - 100% | C5: 19.315 | D5: 24.006 | E5: 37.491 | F5: 42.905 | G5: 65.225 | H5: 108.249 | I5: 156.508 | J5: 170.91 | K5: 182.795 | L5: 233.715 | M5: =IS!M4 -> 215.639 | N5: =IS!N4 -> 229.234 | O5: =IS!O4 -> 265.595 | P5: =IS!P4 -> 260.174 | Q5: =IS!Q4 -> 274.515 | R5: =IS!R4 -> 365.817 | S5: =IS!S4 -> 394 | T5: =IS!T4 -> 383 | ... V5: =IS!V4 -> 416.161
B6: Cost of sales | C6: =-IS!C5/IS!C$4 -> 0.71017344 | D6: =-IS!D5/IS!D$4 -> 0.66033492 | E6: =-IS!E5/IS!E$4 -> 0.64799552 | F6: =-IS!F5/IS!F$4 -> 0.59860156 | G6: =-IS!G5/IS!G$4 -> 0.60622461 | H6: =-IS!H5/IS!H$4 -> 0.59521104 | I6: =-IS!I5/IS!I$4 -> 0.5612876 | J6: =-IS!J5/IS!J$4 -> 0.62375519 | ... V6: =-IS!V5/IS!V$4 -> 0.53094836
B7: Gross margin | C7: =IS!C6/IS!C$4 -> 0.28982656 | D7: =IS!D6/IS!D$4 -> 0.33966508 | E7: =IS!E6/IS!E$4 -> 0.35200448 | F7: =IS!F6/IS!F$4 -> 0.40139844 | G7: =IS!G6/IS!G$4 -> 0.39377539 | H7: =IS!H6/IS!H$4 -> 0.40478896 | I7: =IS!I6/IS!I$4 -> 0.4387124 | J7: =IS!J6/IS!J$4 -> 0.37624481 | ... V7: =IS!V6/IS!V$4 -> 0.46905164
B8: Total operating expenses | C8: =-IS!C7/IS!C$4 -> 0.16282682 | D8: =-IS!D7/IS!D$4 -> 0.15600267 | E8: =-IS!E7/IS!E$4 -> 0.12989784 | F8: =-IS!F7/IS!F$4 -> 0.12777066 | G8: =-IS!G7/IS!G$4 -> 0.11190494 | H8: =-IS!H7/IS!H$4 -> 0.092638269 | I8: =-IS!I7/IS!I$4 -> 0.085752805 | J8: =-IS!J7/IS!J$4 -> 0.089550056 | ... V8: =-IS!V7/IS!V$4 -> 0.14922109
B9: Research and development | C9: =-IS!C8/IS!C$4 -> 0.036862542 | D9: =-IS!D8/IS!D$4 -> 0.03257519 | E9: =-IS!E8/IS!E$4 -> 0.029580433 | F9: =-IS!F8/IS!F$4 -> 0.03106864 | G9: =-IS!G8/IS!G$4 -> 0.027320813 | H9: =-IS!H8/IS!H$4 -> 0.022439006 | I9: =-IS!I8/IS!I$4 -> 0.02160273 | J9: =-IS!J8/IS!J$4 -> 0.026183371 | ... V9: =-IS!V8/IS!V$4 -> 0.083020754
B10: Selling, general and administrative | C10: =-IS!C9/IS!C$4 -> 0.12596428 | D10: =-IS!D9/IS!D$4 -> 0.12342748 | E10: =-IS!E9/IS!E$4 -> 0.10031741 | F10: =-IS!F9/IS!F$4 -> 0.096702016 | G10: =-IS!G9/IS!G$4 -> 0.084584132 | H10: =-IS!H9/IS!H$4 -> 0.070199263 | I10: =-IS!I9/IS!I$4 -> 0.064150075 | J10: =-IS!J9/IS!J$4 -> 0.063366684 | ... V10: =-IS!V9/IS!V$4 -> 0.066322889
B11: Operating income | C11: =IS!C10/IS!C$4 -> 0.12699974 | D11: =IS!D10/IS!D$4 -> 0.18366242 | E11: =IS!E10/IS!E$4 -> 0.22210664 | F11: =IS!F10/IS!F$4 -> 0.27362778 | G11: =IS!G10/IS!G$4 -> 0.28187045 | H11: =IS!H10/IS!H$4 -> 0.31215069 | I11: =IS!I10/IS!I$4 -> 0.35295959 | J11: =IS!J10/IS!J$4 -> 0.28669475 | ... V11: =IS!V10/IS!V$4 -> 0.319708
B12: Other income / expense, net | C12: =-IS!C11/IS!C$4 -> -0.01889723 | D12: =-IS!D11/IS!D$4 -> -0.024952095 | E12: =-IS!E11/IS!E$4 -> -0.016537302 | F12: =-IS!F11/IS!F$4 -> -0.007598182 | G12: =-IS!G11/IS!G$4 -> -0.0023763894 | H12: =-IS!H11/IS!H$4 -> -0.0038337537 | I12: =-IS!I11/IS!I$4 -> -0.0033352928 | J12: =-IS!J11/IS!J$4 -> -0.0067637938 | ... V12: =-IS!V11/IS!V$4 -> 0.00077133609
B13: Income before taxes | C13: =IS!C12/IS!C$4 -> 0.14589697 | D13: =IS!D12/IS!D$4 -> 0.20861451 | E13: =IS!E12/IS!E$4 -> 0.23864394 | F13: =IS!F12/IS!F$4 -> 0.28122596 | G13: =IS!G12/IS!G$4 -> 0.28424684 | H13: =IS!H12/IS!H$4 -> 0.31598444 | I13: =IS!I12/IS!I$4 -> 0.35629489 | J13: =IS!J12/IS!J$4 -> 0.29345855 | ... V13: =IS!V12/IS!V$4 -> 0.31893666
B14: Provision for income taxes | C14: =-IS!C13/IS!C$4 -> 0.04292001 | D14: =-IS!D13/IS!D$4 -> 0.062984254 | E14: =-IS!E13/IS!E$4 -> 0.075431437 | F14: =-IS!F13/IS!F$4 -> 0.089290293 | G14: =-IS!G13/IS!G$4 -> 0.069405903 | H14: =-IS!H13/IS!H$4 -> 0.076518028 | I14: =-IS!I13/IS!I$4 -> 0.08964398 | J14: =-IS!J13/IS!J$4 -> 0.076753847 | ... V14: =-IS!V13/IS!V$4 -> 0.04978602
B15: Net income | C15: =IS!C14/IS!C$4 -> 0.10297696 | D15: =IS!D14/IS!D$4 -> 0.14563026 | E15: =IS!E14/IS!E$4 -> 0.1632125 | F15: =IS!F14/IS!F$4 -> 0.19193567 | G15: =IS!G14/IS!G$4 -> 0.21484094 | H15: =IS!H14/IS!H$4 -> 0.23946642 | I15: =IS!I14/IS!I$4 -> 0.26665091 | J15: =IS!J14/IS!J$4 -> 0.2167047 | ... V15: =IS!V14/IS!V$4 -> 0.26915064
B17: Sales growth | D17: =(D5-C5)/C5 -> 0.24286824 | E17: =(E5-D5)/D5 -> 0.56173457 | F17: =(F5-E5)/E5 -> 0.14440799 | G17: =(G5-F5)/F5 -> 0.52021909 | H17: =(H5-G5)/G5 -> 0.65962438 | I17: =(I5-H5)/H5 -> 0.44581474 | J17: =(J5-I5)/I5 -> 0.092020855 | K17: =(K5-J5)/J5 -> 0.069539524 | ... V17: =(V5-U5)/U5 -> 0.064350384
