Workbook
Name Balance_Sheet: 'P6-MSFT-leverage'!$B$3:$F$47
Name Balance_Sheet: 'MSFT - BS'!$B$3:$F$48
Name Cash_Flow: 'MSFT - CF'!$B$3:$E$47
Name Fin_Operating_Segment_History: 'MSFT - segment info'!$C$7:$C$9,'MSFT - segment info'!$E$7:$E$9,'MSFT - segment info'!$C$14:$C$16,'MSFT - segment info'!$E$14:$E$16
Name Fin_Operating_Segment_History: '[1]Segment History'!$B$6:$F$8,'[1]Segment History'!$H$6:$L$8,'[1]Segment History'!$B$13:$F$15,'[1]Segment History'!$H$13:$L$15
Name Income_Statement: #REF!
Name Yearly_Income_Statements: 'MSFT - IS'!$C$7:$G$28

Sheet MSFT - BS
B2: MICROSOFT CORPORATION
B3: BALANCE SHEETS
B4: (In millions) (Unaudited)
D6: ='MSFT - IS'!E6 -> FY22 | E6: ='MSFT - IS'!F6 -> FY23 | F6: ='MSFT - IS'!G6 -> FY24 | G6: ='MSFT - IS'!H6 -> FY25
B7: Assets
B8: Current assets:
B9: Cash and cash equivalents | D9: 13931 | E9: 34704 | F9: 18315 | G9: 30242
B10: Short-term investments | D10: 90826 | E10: 76558 | F10: 57228 | G10: 64323
B11: Total cash, cash equivalents, and short-term investments | D11: 104757 | E11: 111262 | F11: 75543 | G11: 94565
B12: Accounts receivable, net of allowance for doubtful accounts | D12: 44261 | E12: 48688 | F12: 56924 | G12: 69905
B13: Inventories | D13: 3742 | E13: 2500 | F13: 1246 | G13: 938
B14: Other current assets | D14: 16924 | E14: 21807 | F14: 26021 | G14: 25723
B15: Total current assets | D15: 169684 | E15: 184257 | F15: 159734 | G15: 191131
B16: Property and equipment, net of accumulated depreciation of $93,653 and $76,421 | D16: 74398 | E16: 95641 | F16: 135591 | G16: 204966
B17: Operating lease right-of-use assets | D17: 13148 | E17: 14346 | F17: 18961 | G17: 24823
B18: Equity and other investments | D18: 6891 | E18: 9879 | F18: 14600 | G18: 15405
B19: Goodwill | D19: 67524 | E19: 67886 | F19: 119220 | G19: 119509
B20: Intangible assets, net | D20: 11298 | E20: 9366 | F20: 27597 | G20: 22604
... B22: Total assets | D22: 364840 | E22: 411976 | F22: 512163 | G22: 619003
B23: Liabilities and stockholders' equity
B24: Current liabilities:
B25: Accounts payable | D25: 19000 | E25: 18095 | F25: 21996 | G25: 27724
B26: Short-term debt | F26: 6693 | G26: 0
B27: Current portion of long-term debt | D27: 2749 | E27: 5247 | F27: 2249 | G27: 2999
B28: Accrued compensation | D28: 10661 | E28: 11009 | F28: 12564 | G28: 13709
B29: Short-term income taxes | D29: 4067 | E29: 4152 | F29: 5017 | G29: 7211
B30: Short-term unearned revenue | D30: 45538 | E30: 50901 | F30: 57582 | G30: 64555
B31: Other current liabilities | D31: 13067 | E31: 14745 | F31: 19185 | G31: 25020
B32: Total current liabilities | D32: 47032 | E32: 41990 | F32: 125286 | G32: 141218
B33: Long-term debt | D33: 47032 | E33: 41990 | F33: 42688 | G33: 40152
B34: Long-term income taxes | D34: 26069 | E34: 25560 | F34: 27931 | G34: 25986
B35: Long-term unearned revenue | D35: 2870 | E35: 2912 | F35: 2602 | G35: 2710
B36: Deferred income taxes | D36: 230 | E36: 433 | F36: 2618 | G36: 2835
B37: Operating lease liabilities | D37: 11489 | E37: 12728 | F37: 15497 | G37: 17437
B38: Other long-term liabilities | D38: 15526 | E38: 17981 | F38: 27064 | G38: 45186
B39: Total liabilities | D39: 198298 | E39: 205753 | F39: 243686 | G39: 275524
B40: Commitments and contingencies
B41: Stockholders' equity:
B42: Common stock and paid-in capital - shares authorized 24,000; outstanding 7,434 and 7,434 | D42: 86939 | E42: 93718 | F42: 100923 | G42: 109095
B43: Retained earnings | D43: 84281 | E43: 118848 | F43: 173144 | G43: 237731
...

Sheet MSFT - IS
B2: MICROSOFT CORPORATION
B3: INCOME STATEMENTS
B4: (In millions, except per share amounts)
C6: FY20 | D6: FY21 | E6: FY22 | F6: FY23 | G6: FY24 | H6: FY25
B7: Revenue:
B8: Product | C8: 68041 | D8: 71074 | E8: 72732 | F8: 64699 | G8: 64773 | H8: 63946
B9: Service and other | C9: 74974 | D9: 97014 | E9: 125538 | F9: 147216 | G9: 180349 | H9: 217778
B10: Total revenue | C10: 143015 | D10: 168088 | E10: 198270 | F10: 211915 | G10: 245122 | H10: 281724
B11: Cost of revenue:
B12: Product | C12: 16017 | D12: 18219 | E12: 19064 | F12: 17804 | G12: 15272 | H12: 13501
B13: Service and other | C13: 30061 | D13: 34013 | E13: 43586 | F13: 48059 | G13: 58842 | H13: 74330
B14: Total cost of revenue | C14: 46078 | D14: 52232 | E14: 62650 | F14: 65863 | G14: 74114 | H14: 87831
B15: Gross margin | C15: 96937 | D15: 115856 | E15: 135620 | F15: 146052 | G15: 171008 | H15: 193893
B16: Research and development | C16: 19269 | D16: 20716 | E16: 24512 | F16: 27195 | G16: 29510 | H16: 32488
B17: Sales and marketing | C17: 19598 | D17: 20117 | E17: 21825 | F17: 22759 | G17: 24456 | H17: 25654
B18: General and administrative | C18: 5111 | D18: 5107 | E18: 5900 | F18: 7575 | G18: 7609 | H18: 7223
B19: Impairment and restructuring | C19: 0 | D19: 0 | E19: 0 | F19: 0 | G19: 0 | H19: 0
B20: Operating income | C20: 52959 | D20: 69916 | E20: 83383 | F20: 88523 | G20: 109433 | H20: 128528
B21: Other income (expense), net | C21: 77 | D21: 1186 | E21: 333 | F21: 788 | G21: -1646 | H21: -4901
B22: Income before income taxes | C22: 53036 | D22: 71102 | E22: 83716 | F22: 89311 | G22: 107787 | H22: 123627
B23: Provision for income taxes | C23: 8755 | D23: 9831 | E23: 10978 | F23: 16950 | G23: 19651 | H23: 21795
B24: Net income | C24: 44281 | D24: 61271 | E24: 72738 | F24: 72361 | G24: 88136 | H24: 101832
B25: Earnings per share:
B26: Basic | C26: 5.82 | D26: 8.12 | E26: 9.7 | F26: 9.72 | G26: 11.86 | H26: 13.7
B27: Diluted | C27: 5.76 | D27: 8.05 | E27: 9.65 | F27: 9.68 | G27: 11.8 | H27: 13.64
B30: Interest expense | C30: 2591 | D30: 2346 | E30: 2063 | F30: 1968 | G30: 2935 | H30: 2385

Sheet MSFT - CF
B2: MICROSOFT CORPORATION
B3: CASH FLOWS STATEMENTS
B4: (In millions) (Unaudited)
C6: ='MSFT - IS'!E6 -> FY22 | D6: ='MSFT - IS'!F6 -> FY23 | E6: ='MSFT - IS'!G6 -> FY24 | F6: ='MSFT - IS'!H6 -> FY25
B7: Operations
B8: Net income | C8: 72738 | D8: 72361 | E8: 88136 | F8: 101832
B9: Adjustments to reconcile net income to net cash from operations:
B10: Depreciation, amortization, and other | C10: 14460 | D10: 13861 | E10: 22287 | F10: 34153
B11: Stock-based compensation expense | C11: 7502 | D11: 9611 | E11: 10734 | F11: 11974
B12: Net recognized losses on investments and derivatives | C12: -409 | D12: 196 | E12: 305 | F12: 609
B13: Deferred income taxes | C13: -5702 | D13: -6059 | E13: -4738 | F13: -7056
B14: Changes in operating assets and liabilities:
B15: Accounts receivable | C15: -6834 | D15: -4087 | E15: -7191 | F15: -10581
B16: Inventories | C16: -1123 | D16: 1242 | E16: 1284 | F16: 309
B17: Other current assets | C17: -709 | D17: -1991 | E17: -1648 | F17: -3044
B18: Other long-term assets | C18: -2805 | D18: -2833 | E18: -6817 | F18: -2950
B19: Accounts payable | C19: 2943 | D19: -2721 | E19: 3545 | F19: 569
B20: Unearned revenue | C20: 5109 | D20: 5535 | E20: 5348 | F20: 5438
B21: Income taxes | C21: 696 | D21: -358 | E21: 1687 | F21: -38
B22: Other current liabilities | C22: 2344 | D22: 2272 | E22: 4867 | F22: 5922
B23: Other long-term liabilities | C23: 825 | D23: 553 | E23: 749 | F23: -975
B24: Net cash from operations | C24: 89035 | D24: 87582 | E24: 118548 | F24: 136162
B25: Financing
B26: Proceeds from issuance (repayments) of debt, maturities of 90 days or less, net | C26: 0 | D26: 0 | E26: 5250 | F26: -5746
B27: Proceeds from issuance of debt | C27: 0 | D27: 0 | E27: 24395 | F27: 0
B28: Repayments of debt | C28: -9023 | D28: -2750 | E28: -29070 | F28: -3216
B29: Common stock issued | C29: 1841 | D29: 1866 | E29: 2002 | F29: 2056
B30: Common stock repurchased | C30: -32696 | D30: -22245 | E30: -17254 | F30: -18420
B31: Common stock cash dividends paid | C31: -18135 | D31: -19800 | E31: -21771 | F31: -24082
B32: Other, net | C32: -863 | D32: -1006 | E32: -1309 | F32: -2291
B33: Net cash used in financing | C33: -58876 | D33: -43935 | E33: -37757 | F33: -51699
B34: Investing
B35: Additions to property and equipment | C35: -23886 | D35: -28107 | E35: -44477 | F35: -64551
B36: Acquisition of companies, net of cash acquired and divestitures, and purchases of intangible and other assets | C36: -22038 | D36: -1670 | E36: -69132 | F36: -5978
B37: Purchases of investments | C37: -26456 | D37: -37651 | E37: -17732 | F37: -29775
B38: Maturities of investments | C38: 16451 | D38: 33510 | E38: 24775 | F38: 16079
B39: Sales of investments | C39: 28443 | D39: 14354 | E39: 10894 | F39: 9309
B40: Other, net | C40: -2825 | D40: -3116 | E40: -1298 | F40: 2317
B41: Net cash used in investing | C41: -30311 | D41: -22680 | E41: -96970 | F41: -72599
B42: Effect of foreign exchange rates on cash and cash equivalents | C42: -141 | D42: -194 | E42: -210 | F42: 63
...

Sheet MSFT - segment info
B2: Microsoft Corporation
B3: Segment Revenue and Operating Income
B4: (In millions)
B6: Revenue | C6: Fiscal Year 2023 | E6: Fiscal Year 2024 | G6: Fiscal Year 2025
B7: Productivity and Business Processes | C7: 94151 | E7: 106820 | G7: 120810
B8: Intelligent Cloud | C8: 72944 | E8: 87464 | G8: 106265
B9: More Personal Computing | C9: 44820 | E9: 50838 | G9: 54649
B10: Total | C10: 211915 | E10: 245122 | G10: 281724
B13: Operating Income | C13: Fiscal Year 2023 | E13: Fiscal Year 2024 | G13: Fiscal Year 2025
B14: Productivity and Business Processes | C14: 50074 | E14: 59661 | G14: 69773
B15: Intelligent Cloud | C15: 28411 | E15: 37813 | G15: 44589
B16: More Personal Computing | C16: 10038 | E16: 11959 | G16: 14166
B17: Total | C17: 88523 | E17: 109433 | G17: 128528
B21: Operating profit margins
B22: Productivity and Business Processes | C22: =C14/C7 -> 0.53184778 | E22: =E14/E7 -> 0.558519 | G22: =G14/G7 -> 0.57754325
B23: Intelligent Cloud | C23: =C15/C8 -> 0.38949057 | E23: =E15/E8 -> 0.43232644 | G23: =G15/G8 -> 0.41960194
B24: More Personal Computing | C24: =C16/C9 -> 0.22396252 | E24: =E16/E9 -> 0.23523742 | G24: =G16/G9 -> 0.25921792
B26: Revenue growth rates
B27: Productivity and Business Processes | E27: =E7/C7-1 -> 0.13456044 | G27: =G7/E7-1 -> 0.13096798
B28: Intelligent Cloud | E28: =E8/C8-1 -> 0.19905681 | G28: =G8/E8-1 -> 0.21495701
B29: More Personal Computing | E29: =E9/C9-1 -> 0.13427041 | G29: =G9/E9-1 -> 0.07496361

Sheet P3- MSFT-AR
B2: MICROSOFT CORPORATION
B3: AR data
B5: In $'M | C5: 2022 | D5: 2023 | E5: 2024 | F5: 2025
B6: Gross AR | C6: =SUM(C7:C8) -> 44894 | D6: =SUM(D7:D8) -> 49338 | E6: =SUM(E7:E8) -> 57754 | F6: =SUM(F7:F8) -> 70849
B7: Allowance for uncollectable accounts | C7: 633 | D7: 650 | E7: 830 | F7: 944
B8: Net AR | C8: ='MSFT - BS'!D12 -> 44261 | D8: ='MSFT - BS'!E12 -> 48688 | E8: ='MSFT - BS'!F12 -> 56924 | F8: ='MSFT - BS'!G12 -> 69905
B9: Bad debt expense | F9: 870
A11: 3A | B11: Allowance as % of gross AR | C11: =C7/C6 -> 0.01409988 | D11: =D7/D6 -> 0.013174429 | E11: =E7/E6 -> 0.014371299 | F11: =F7/F6 -> 0.013324112
A13: 3C | B13: Write off the most recent year | F13: =E7+F9-F7 -> 756

Sheet P4-WMT-IS and BS
B2: Walmart - Income statement - selected items
C4: January, 2024 | D4: January, 2025
B5: Revenues | C5: 648125 | D5: 680985
B6: Cost of sales | C6: 490142 | D6: 511753
B7: Gross profit | C7: =C5-C6 -> 157983 | D7: =D5-D6 -> 169232
B8: Total selling and administrative expense | C8: 130971 | D8: 139884
B9: Operating income | C9: 27012 | D9: 29348
B10: NET INCOME | C10: 16270 | D10: 20157
B12: Walmart - Balance sheet - selected items
B14: Current assets:
B15: Cash and equivalents | C15: 9867 | D15: 9037
B16: Accounts receivable, net | C16: 8796 | D16: 9975
B17: Inventories | C17: 54892 | D17: 56435
B18: Total current assets | C18: 76877 | D18: 79458
B20: Current liabilities:
B21: Current portion of long-term debt | C21: 878 | D21: 3068
B22: Accounts payable | C22: 56812 | D22: 58666
B23: Total current liabilities | C23: 92415 | D23: 96584
B24: Total liabilities | C24: 162050 | D24: 163402
B25: Equity | C25: 90349 | D25: 97421
A28: 4A | B28: Days AR | D28: =AVERAGE(C16:D16)/(D5/365) -> 5.0305183
B29: Days Inventory | D29: =AVERAGE(C17:D17)/(D6/365) -> 39.70114
B30: Days AP | D30: =AVERAGE(C22:D22)/(D6/365) -> 41.181459
B31: Days AR plus Days Inventory minus Days AP | D31: =D28+D29-D30 -> 3.5501997

Sheet P4-TGT-IS and BS
B2: Target - Income statement - selected items
C4: February, 2024 | D4: February, 2025
B5: Net revenue | C5: 107412 | D5: 106566
B6: Cost of goods sold | C6: 77828 | D6: 76502
B7: Selling, general, and administrative expenses | C7: 21462 | D7: 21969
B8: Income from operations | C8: 5707 | D8: 5566
B9: Net income | C9: 4138 | D9: 4091
B11: Target - Balance sheet - selected items
B13: Current assets
B14: Cash and cash equivalents | C14: 3805 | D14: 4762
B15: Accounts receivable, net | C15: 891 | D15: 998
B16: Inventories | C16: 11886 | D16: 12740
B17: Other current assets | C17: 1807 | D17: 1952
B18: Total current assets | C18: 17498 | D18: 19454
B20: Current liabilities
B21: Accounts payable | C21: 12098 | D21: 13053
B22: Total current liabilities | C22: 19304 | D22: 20799
B23: Total liabilities | C23: 41924 | D23: 43103
B24: Equity | C24: 13432 | D24: 14666
A27: 4A | B27: Days AR | D27: =AVERAGE(C15:D15)/(D5/365) -> 3.235014
B28: Days Inventory | D28: =AVERAGE(C16:D16)/(D6/365) -> 58.746765
B29: Days AP | D29: =AVERAGE(C21:D21)/(D6/365) -> 59.999183
B30: Days AR plus Days Inventory minus Days AP | D30: =D27+D28-D29 -> 1.9825957

Sheet P5-MSFT-PPE
B2: MICROSOFT CORPORATION
B3: PPE - Data centers expansion and expense
B5: Value of new data center equipment | C5: 60000
B7: Option 1 - straight line with useful life | C7: 6
B8: Option 2 - straight line with useful life | C8: 3
B9: Option 3 - double-declining with useful life | C9: 6
B10: Tax rate | C10: 0.21
B11: Sale year | C11: 2
B12: Sale price in 2 years | C12: 20000
A14: 5A | B14: Depreciation expense option 1 | C14: =C5/C7 -> 10000
B15: Depreciation expense option 2 | C15: =C5/C8 -> 20000
B16: Depreciation expense option 3 | C16: =C5*2/C9 -> 20000
A18: 5B | B18: Current operating income | C18: ='MSFT - IS'!H20 -> 128528
B19: Difference between the depreciaiton expense | C19: =C15-C14 -> 10000
B20: Extra depreciation as % of ops income | C20: =C19/C18 -> 0.077804058
A23: 5C | B23: Proceeds from sale incl tax effect
B24: Option 1:
B25: Sale in two years | C25: =C12 -> 20000
B26: Book value at the end of the second year | C26: =C5-C11*C14 -> 40000
B27: Gain/(loss) on sale | C27: =C25-C26 -> -20000
B28: Tax owned / (credit) from the sale | C28: =C10*C27 -> -4200
B29: Total | C29: =C25-C28 -> 24200
B31: Option 2:
B32: Sale in two years | C32: =C12 -> 20000
B33: Book value at the end of the second year | C33: =C5-C11*C15 -> 20000
B34: Gain/(loss) on sale | C34: =C32-C33 -> 0
B35: Tax owned / (credit) from the sale | C35: =C17*C34 -> 0
B36: Total | C36: =C32-C35 -> 20000

Sheet P6-MSFT-leverage
B2: MICROSOFT CORPORATION
B3: BALANCE SHEETS
D5: June 30, 2022 | E5: June 30, 2023 | F5: June 30, 2024 | G5: June 30, 2025
B6: Assets
B7: Current assets:
B8: Cash and cash equivalents | D8: 13931 | E8: 34704 | F8: 18315 | G8: 30242
B9: Short-term investments | D9: 90826 | E9: 76558 | F9: 57228 | G9: 64323
B10: Total cash, cash equivalents, and short-term investments | D10: 104757 | E10: 111262 | F10: 75543 | G10: 94565
B11: Accounts receivable, net of allowance for doubtful accounts | D11: 44261 | E11: 48688 | F11: 56924 | G11: 69905
B12: Inventories | D12: 3742 | E12: 2500 | F12: 1246 | G12: 938
B13: Other current assets | D13: 16924 | E13: 21807 | F13: 26021 | G13: 25723
B14: Total current assets | D14: 169684 | E14: 184257 | F14: 159734 | G14: 191131
B15: Property and equipment, net of accumulated depreciation of $93,653 and $76,421 | D15: 74398 | E15: 95641 | F15: 135591 | G15: 204966
B16: Operating lease right-of-use assets | D16: 13148 | E16: 14346 | F16: 18961 | G16: 24823
B17: Equity and other investments | D17: 6891 | E17: 9879 | F17: 14600 | G17: 15405
B18: Goodwill | D18: 67524 | E18: 67886 | F18: 119220 | G18: 119509
B19: Intangible assets, net | D19: 11298 | E19: 9366 | F19: 27597 | G19: 22604
... B21: Total assets | D21: 364840 | E21: 411976 | F21: 512163 | G21: 619003
B22: Liabilities and stockholders' equity
B23: Current liabilities:
B24: Accounts payable | D24: 19000 | E24: 18095 | F24: 21996 | G24: 27724
B25: Short-term debt | F25: 6693 | G25: 0
B26: Current portion of long-term debt | D26: 2749 | E26: 5247 | F26: 2249 | G26: 2999
B27: Accrued compensation | D27: 10661 | E27: 11009 | F27: 12564 | G27: 13709
B28: Short-term income taxes | D28: 4067 | E28: 4152 | F28: 5017 | G28: 7211
B29: Short-term unearned revenue | D29: 45538 | E29: 50901 | F29: 57582 | G29: 64555
B30: Other current liabilities | D30: 13067 | E30: 14745 | F30: 19185 | G30: 25020
B31: Total current liabilities | D31: 47032 | E31: 41990 | F31: 125286 | G31: 141218
B32: Long-term debt | D32: 47032 | E32: 41990 | F32: 42688 | G32: 40152
B33: Long-term income taxes | D33: 26069 | E33: 25560 | F33: 27931 | G33: 25986
B34: Long-term unearned revenue | D34: 2870 | E34: 2912 | F34: 2602 | G34: 2710
B35: Deferred income taxes | D35: 230 | E35: 433 | F35: 2618 | G35: 2835
B36: Operating lease liabilities | D36: 11489 | E36: 12728 | F36: 15497 | G36: 17437
B37: Other long-term liabilities | D37: 15526 | E37: 17981 | F37: 27064 | G37: 45186
B38: Total liabilities | D38: 198298 | E38: 205753 | F38: 243686 | G38: 275524
B39: Commitments and contingencies
B40: Stockholders' equity:
B41: Common stock and paid-in capital - shares authorized 24,000; outstanding 7,434 and 7,434 | D41: 86939 | E41: 93718 | F41: 100923 | G41: 109095
B42: Retained earnings | D42: 84281 | E42: 118848 | F42: 173144 | G42: 237731
B43: Accumulated other comprehensive loss | D43: -4678 | E43: -6343 | F43: -5590 | G43: -3347
...

Sheet P8-CF statement
B2: Cash flow statement preparation
B4: ABC Company
B6: Inputs | D6: Current year
B7: Sale of equipment | D7: 15000
B8: Equipment book value | D8: 20000
B9: Dividends paid | D9: 15000
B10: Shares issued (in $) | D10: 35000
B12: Income statement | D12: Current year
B13: Sales | D13: 300000
B14: COGS | D14: -120000
B15: Wages expense | D15: -80000
B16: Advertising | D16: -17000
B17: Depreciation | D17: -12000
B18: Interest expense | D18: -700
B19: Loss on sale of equipment | D19: -5000
B20: Net income | D20: =SUM(D13:D19) -> 65300
B22: Balance sheet | C22: Prior year | D22: Current year
B23: Cash | C23: 45000 | D23: 50600
B24: AR | C24: 50000 | D24: 35000
B25: Inventory | C25: 108000 | D25: 125000
B26: Prepaid Advertising | C26: 13000 | D26: 16000
B27: PPE, gross | C27: 290000 | D27: 340000
B28: Accumulated depreciation | C28: -56000 | D28: -68000
B29: Total assets | C29: =SUM(C23:C28) -> 450000 | D29: =SUM(D23:D28) -> 498600
B31: AP | C31: 15200 | D31: 19000
B32: Interest payable | C32: 800 | D32: 300
B33: Long-term loan | C33: 120000 | D33: 80000
B34: Common stock | C34: 220000 | D34: 255000
B35: Retained earnings | C35: 94000 | D35: 144300
B36: Total liabilities and equity | C36: =SUM(C31:C35) -> 450000 | D36: =SUM(D31:D35) -> 498600
B38: Cash flow statement | D38: Current year
B39: Net income | D39: =D20 -> 65300
B40: Depreciation | D40: =-D17 -> 12000
B41: Loss on sale of equipment | D41: =-D19 -> 5000
B42: Change in AR | D42: =C24-D24 -> 15000
B43: Change in Inventory | D43: =C25-D25 -> -17000
B44: Change in Prepaid advertising | D44: =C26-D26 -> -3000
B45: Change in AP | D45: =D31-C31 -> 3800
B46: Change in Interest payable | D46: =D32-C32 -> -500
B47: Net cash from operating activities | D47: =SUM(D39:D46) -> 80600
...
